{
 "cells": [
  {
   "cell_type": "markdown",
   "source": [
    "# Testing the functions work correctly"
   ],
   "metadata": {
    "collapsed": false
   }
  },
  {
   "cell_type": "code",
   "execution_count": 28,
   "outputs": [],
   "source": [
    "import pickle5\n",
    "from phynteny_utils import train_model\n",
    "from phynteny_utils import format_data\n"
   ],
   "metadata": {
    "collapsed": false
   }
  },
  {
   "cell_type": "code",
   "execution_count": 105,
   "outputs": [
    {
     "data": {
      "text/plain": "<module 'phynteny_utils.train_model' from '/Users/susiegrigson/PycharmProjects/Phynteny/phynteny_utils/train_model.py'>"
     },
     "execution_count": 105,
     "metadata": {},
     "output_type": "execute_result"
    }
   ],
   "source": [
    "from importlib import reload\n",
    "reload(train_model)\n",
    "#reload(format_data)"
   ],
   "metadata": {
    "collapsed": false
   }
  },
  {
   "cell_type": "code",
   "execution_count": 97,
   "outputs": [],
   "source": [
    "prophage_dict =pickle5.load(open('test_data/test_training_data.pkl', 'rb'))\n",
    "subset_keys = list(prophage_dict.keys())[0:10]\n",
    "subset_dict = dict(zip(subset_keys, [prophage_dict.get(i) for i in subset_keys]))"
   ],
   "metadata": {
    "collapsed": false
   }
  },
  {
   "cell_type": "code",
   "execution_count": 91,
   "outputs": [
    {
     "data": {
      "text/plain": "(10, 120, 16)"
     },
     "execution_count": 91,
     "metadata": {},
     "output_type": "execute_result"
    }
   ],
   "source": [
    "X, y, masked_idx = format_data.generate_dataset(subset_dict, 'all', 10, 120)\n",
    "X.shape"
   ],
   "metadata": {
    "collapsed": false
   }
  },
  {
   "cell_type": "code",
   "execution_count": 106,
   "outputs": [
    {
     "name": "stdout",
     "output_type": "stream",
     "text": [
      "KerasClassifier(\n",
      "\tmodel=<function generate_LSTM at 0x7fa72b9178b0>\n",
      "\tbuild_fn=None\n",
      "\twarm_start=False\n",
      "\trandom_state=None\n",
      "\toptimizer=rmsprop\n",
      "\tloss=None\n",
      "\tmetrics=None\n",
      "\tbatch_size=None\n",
      "\tvalidation_batch_size=None\n",
      "\tverbose=0\n",
      "\tcallbacks=None\n",
      "\tvalidation_split=0.0\n",
      "\tshuffle=True\n",
      "\trun_eagerly=False\n",
      "\tepochs=1\n",
      "\tclass_weight=None\n",
      ")\n",
      "(10, 1920)\n"
     ]
    },
    {
     "ename": "ValueError",
     "evalue": "\nAll the 15 fits failed.\nIt is very likely that your model is misconfigured.\nYou can try to debug the error by setting error_score='raise'.\n\nBelow are more details about the failures:\n--------------------------------------------------------------------------------\n1 fits failed with the following error:\nTraceback (most recent call last):\n  File \"/Users/susiegrigson/opt/anaconda3/envs/phynteny/lib/python3.8/site-packages/sklearn/model_selection/_validation.py\", line 686, in _fit_and_score\n    estimator.fit(X_train, y_train, **fit_params)\n  File \"/Users/susiegrigson/opt/anaconda3/envs/phynteny/lib/python3.8/site-packages/scikeras/wrappers.py\", line 1494, in fit\n    super().fit(X=X, y=y, sample_weight=sample_weight, **kwargs)\n  File \"/Users/susiegrigson/opt/anaconda3/envs/phynteny/lib/python3.8/site-packages/scikeras/wrappers.py\", line 762, in fit\n    self._fit(\n  File \"/Users/susiegrigson/opt/anaconda3/envs/phynteny/lib/python3.8/site-packages/scikeras/wrappers.py\", line 931, in _fit\n    self._fit_keras_model(\n  File \"/Users/susiegrigson/opt/anaconda3/envs/phynteny/lib/python3.8/site-packages/scikeras/wrappers.py\", line 526, in _fit_keras_model\n    hist = self.model_.fit(x=X, y=y, **fit_args)\n  File \"/Users/susiegrigson/opt/anaconda3/envs/phynteny/lib/python3.8/site-packages/keras/utils/traceback_utils.py\", line 70, in error_handler\n    raise e.with_traceback(filtered_tb) from None\n  File \"/var/folders/df/d2hn3bdx7dj7syrpbrxgtzkw0000gn/T/__autograph_generated_fileql9ao1yw.py\", line 15, in tf__train_function\n    retval_ = ag__.converted_call(ag__.ld(step_function), (ag__.ld(self), ag__.ld(iterator)), None, fscope)\nValueError: in user code:\n\n    File \"/Users/susiegrigson/opt/anaconda3/envs/phynteny/lib/python3.8/site-packages/keras/engine/training.py\", line 1160, in train_function  *\n        return step_function(self, iterator)\n    File \"/Users/susiegrigson/opt/anaconda3/envs/phynteny/lib/python3.8/site-packages/keras/engine/training.py\", line 1146, in step_function  **\n        outputs = model.distribute_strategy.run(run_step, args=(data,))\n    File \"/Users/susiegrigson/opt/anaconda3/envs/phynteny/lib/python3.8/site-packages/keras/engine/training.py\", line 1135, in run_step  **\n        outputs = model.train_step(data)\n    File \"/Users/susiegrigson/opt/anaconda3/envs/phynteny/lib/python3.8/site-packages/keras/engine/training.py\", line 993, in train_step\n        y_pred = self(x, training=True)\n    File \"/Users/susiegrigson/opt/anaconda3/envs/phynteny/lib/python3.8/site-packages/keras/utils/traceback_utils.py\", line 70, in error_handler\n        raise e.with_traceback(filtered_tb) from None\n    File \"/Users/susiegrigson/opt/anaconda3/envs/phynteny/lib/python3.8/site-packages/keras/engine/input_spec.py\", line 295, in assert_input_compatibility\n        raise ValueError(\n\n    ValueError: Input 0 of layer \"sequential_9\" is incompatible with the layer: expected shape=(None, 1, 1920), found shape=(None, 1920)\n\n\n--------------------------------------------------------------------------------\n1 fits failed with the following error:\nTraceback (most recent call last):\n  File \"/Users/susiegrigson/opt/anaconda3/envs/phynteny/lib/python3.8/site-packages/sklearn/model_selection/_validation.py\", line 686, in _fit_and_score\n    estimator.fit(X_train, y_train, **fit_params)\n  File \"/Users/susiegrigson/opt/anaconda3/envs/phynteny/lib/python3.8/site-packages/scikeras/wrappers.py\", line 1494, in fit\n    super().fit(X=X, y=y, sample_weight=sample_weight, **kwargs)\n  File \"/Users/susiegrigson/opt/anaconda3/envs/phynteny/lib/python3.8/site-packages/scikeras/wrappers.py\", line 762, in fit\n    self._fit(\n  File \"/Users/susiegrigson/opt/anaconda3/envs/phynteny/lib/python3.8/site-packages/scikeras/wrappers.py\", line 931, in _fit\n    self._fit_keras_model(\n  File \"/Users/susiegrigson/opt/anaconda3/envs/phynteny/lib/python3.8/site-packages/scikeras/wrappers.py\", line 526, in _fit_keras_model\n    hist = self.model_.fit(x=X, y=y, **fit_args)\n  File \"/Users/susiegrigson/opt/anaconda3/envs/phynteny/lib/python3.8/site-packages/keras/utils/traceback_utils.py\", line 70, in error_handler\n    raise e.with_traceback(filtered_tb) from None\n  File \"/var/folders/df/d2hn3bdx7dj7syrpbrxgtzkw0000gn/T/__autograph_generated_filej5ika9tg.py\", line 15, in tf__train_function\n    retval_ = ag__.converted_call(ag__.ld(step_function), (ag__.ld(self), ag__.ld(iterator)), None, fscope)\nValueError: in user code:\n\n    File \"/Users/susiegrigson/opt/anaconda3/envs/phynteny/lib/python3.8/site-packages/keras/engine/training.py\", line 1160, in train_function  *\n        return step_function(self, iterator)\n    File \"/Users/susiegrigson/opt/anaconda3/envs/phynteny/lib/python3.8/site-packages/keras/engine/training.py\", line 1146, in step_function  **\n        outputs = model.distribute_strategy.run(run_step, args=(data,))\n    File \"/Users/susiegrigson/opt/anaconda3/envs/phynteny/lib/python3.8/site-packages/keras/engine/training.py\", line 1135, in run_step  **\n        outputs = model.train_step(data)\n    File \"/Users/susiegrigson/opt/anaconda3/envs/phynteny/lib/python3.8/site-packages/keras/engine/training.py\", line 993, in train_step\n        y_pred = self(x, training=True)\n    File \"/Users/susiegrigson/opt/anaconda3/envs/phynteny/lib/python3.8/site-packages/keras/utils/traceback_utils.py\", line 70, in error_handler\n        raise e.with_traceback(filtered_tb) from None\n    File \"/Users/susiegrigson/opt/anaconda3/envs/phynteny/lib/python3.8/site-packages/keras/engine/input_spec.py\", line 295, in assert_input_compatibility\n        raise ValueError(\n\n    ValueError: Input 0 of layer \"sequential_9\" is incompatible with the layer: expected shape=(None, 1, 1920), found shape=(None, 1920)\n\n\n--------------------------------------------------------------------------------\n1 fits failed with the following error:\nTraceback (most recent call last):\n  File \"/Users/susiegrigson/opt/anaconda3/envs/phynteny/lib/python3.8/site-packages/sklearn/model_selection/_validation.py\", line 686, in _fit_and_score\n    estimator.fit(X_train, y_train, **fit_params)\n  File \"/Users/susiegrigson/opt/anaconda3/envs/phynteny/lib/python3.8/site-packages/scikeras/wrappers.py\", line 1494, in fit\n    super().fit(X=X, y=y, sample_weight=sample_weight, **kwargs)\n  File \"/Users/susiegrigson/opt/anaconda3/envs/phynteny/lib/python3.8/site-packages/scikeras/wrappers.py\", line 762, in fit\n    self._fit(\n  File \"/Users/susiegrigson/opt/anaconda3/envs/phynteny/lib/python3.8/site-packages/scikeras/wrappers.py\", line 931, in _fit\n    self._fit_keras_model(\n  File \"/Users/susiegrigson/opt/anaconda3/envs/phynteny/lib/python3.8/site-packages/scikeras/wrappers.py\", line 526, in _fit_keras_model\n    hist = self.model_.fit(x=X, y=y, **fit_args)\n  File \"/Users/susiegrigson/opt/anaconda3/envs/phynteny/lib/python3.8/site-packages/keras/utils/traceback_utils.py\", line 70, in error_handler\n    raise e.with_traceback(filtered_tb) from None\n  File \"/var/folders/df/d2hn3bdx7dj7syrpbrxgtzkw0000gn/T/__autograph_generated_filean4lp6ve.py\", line 15, in tf__train_function\n    retval_ = ag__.converted_call(ag__.ld(step_function), (ag__.ld(self), ag__.ld(iterator)), None, fscope)\nValueError: in user code:\n\n    File \"/Users/susiegrigson/opt/anaconda3/envs/phynteny/lib/python3.8/site-packages/keras/engine/training.py\", line 1160, in train_function  *\n        return step_function(self, iterator)\n    File \"/Users/susiegrigson/opt/anaconda3/envs/phynteny/lib/python3.8/site-packages/keras/engine/training.py\", line 1146, in step_function  **\n        outputs = model.distribute_strategy.run(run_step, args=(data,))\n    File \"/Users/susiegrigson/opt/anaconda3/envs/phynteny/lib/python3.8/site-packages/keras/engine/training.py\", line 1135, in run_step  **\n        outputs = model.train_step(data)\n    File \"/Users/susiegrigson/opt/anaconda3/envs/phynteny/lib/python3.8/site-packages/keras/engine/training.py\", line 993, in train_step\n        y_pred = self(x, training=True)\n    File \"/Users/susiegrigson/opt/anaconda3/envs/phynteny/lib/python3.8/site-packages/keras/utils/traceback_utils.py\", line 70, in error_handler\n        raise e.with_traceback(filtered_tb) from None\n    File \"/Users/susiegrigson/opt/anaconda3/envs/phynteny/lib/python3.8/site-packages/keras/engine/input_spec.py\", line 295, in assert_input_compatibility\n        raise ValueError(\n\n    ValueError: Input 0 of layer \"sequential_8\" is incompatible with the layer: expected shape=(None, 1, 1920), found shape=(None, 1920)\n\n\n--------------------------------------------------------------------------------\n1 fits failed with the following error:\nTraceback (most recent call last):\n  File \"/Users/susiegrigson/opt/anaconda3/envs/phynteny/lib/python3.8/site-packages/sklearn/model_selection/_validation.py\", line 686, in _fit_and_score\n    estimator.fit(X_train, y_train, **fit_params)\n  File \"/Users/susiegrigson/opt/anaconda3/envs/phynteny/lib/python3.8/site-packages/scikeras/wrappers.py\", line 1494, in fit\n    super().fit(X=X, y=y, sample_weight=sample_weight, **kwargs)\n  File \"/Users/susiegrigson/opt/anaconda3/envs/phynteny/lib/python3.8/site-packages/scikeras/wrappers.py\", line 762, in fit\n    self._fit(\n  File \"/Users/susiegrigson/opt/anaconda3/envs/phynteny/lib/python3.8/site-packages/scikeras/wrappers.py\", line 931, in _fit\n    self._fit_keras_model(\n  File \"/Users/susiegrigson/opt/anaconda3/envs/phynteny/lib/python3.8/site-packages/scikeras/wrappers.py\", line 526, in _fit_keras_model\n    hist = self.model_.fit(x=X, y=y, **fit_args)\n  File \"/Users/susiegrigson/opt/anaconda3/envs/phynteny/lib/python3.8/site-packages/keras/utils/traceback_utils.py\", line 70, in error_handler\n    raise e.with_traceback(filtered_tb) from None\n  File \"/var/folders/df/d2hn3bdx7dj7syrpbrxgtzkw0000gn/T/__autograph_generated_filebkve13vq.py\", line 15, in tf__train_function\n    retval_ = ag__.converted_call(ag__.ld(step_function), (ag__.ld(self), ag__.ld(iterator)), None, fscope)\nValueError: in user code:\n\n    File \"/Users/susiegrigson/opt/anaconda3/envs/phynteny/lib/python3.8/site-packages/keras/engine/training.py\", line 1160, in train_function  *\n        return step_function(self, iterator)\n    File \"/Users/susiegrigson/opt/anaconda3/envs/phynteny/lib/python3.8/site-packages/keras/engine/training.py\", line 1146, in step_function  **\n        outputs = model.distribute_strategy.run(run_step, args=(data,))\n    File \"/Users/susiegrigson/opt/anaconda3/envs/phynteny/lib/python3.8/site-packages/keras/engine/training.py\", line 1135, in run_step  **\n        outputs = model.train_step(data)\n    File \"/Users/susiegrigson/opt/anaconda3/envs/phynteny/lib/python3.8/site-packages/keras/engine/training.py\", line 993, in train_step\n        y_pred = self(x, training=True)\n    File \"/Users/susiegrigson/opt/anaconda3/envs/phynteny/lib/python3.8/site-packages/keras/utils/traceback_utils.py\", line 70, in error_handler\n        raise e.with_traceback(filtered_tb) from None\n    File \"/Users/susiegrigson/opt/anaconda3/envs/phynteny/lib/python3.8/site-packages/keras/engine/input_spec.py\", line 295, in assert_input_compatibility\n        raise ValueError(\n\n    ValueError: Input 0 of layer \"sequential_10\" is incompatible with the layer: expected shape=(None, 1, 1920), found shape=(None, 1920)\n\n\n--------------------------------------------------------------------------------\n1 fits failed with the following error:\nTraceback (most recent call last):\n  File \"/Users/susiegrigson/opt/anaconda3/envs/phynteny/lib/python3.8/site-packages/sklearn/model_selection/_validation.py\", line 686, in _fit_and_score\n    estimator.fit(X_train, y_train, **fit_params)\n  File \"/Users/susiegrigson/opt/anaconda3/envs/phynteny/lib/python3.8/site-packages/scikeras/wrappers.py\", line 1494, in fit\n    super().fit(X=X, y=y, sample_weight=sample_weight, **kwargs)\n  File \"/Users/susiegrigson/opt/anaconda3/envs/phynteny/lib/python3.8/site-packages/scikeras/wrappers.py\", line 762, in fit\n    self._fit(\n  File \"/Users/susiegrigson/opt/anaconda3/envs/phynteny/lib/python3.8/site-packages/scikeras/wrappers.py\", line 931, in _fit\n    self._fit_keras_model(\n  File \"/Users/susiegrigson/opt/anaconda3/envs/phynteny/lib/python3.8/site-packages/scikeras/wrappers.py\", line 526, in _fit_keras_model\n    hist = self.model_.fit(x=X, y=y, **fit_args)\n  File \"/Users/susiegrigson/opt/anaconda3/envs/phynteny/lib/python3.8/site-packages/keras/utils/traceback_utils.py\", line 70, in error_handler\n    raise e.with_traceback(filtered_tb) from None\n  File \"/var/folders/df/d2hn3bdx7dj7syrpbrxgtzkw0000gn/T/__autograph_generated_fileuin_5wmx.py\", line 15, in tf__train_function\n    retval_ = ag__.converted_call(ag__.ld(step_function), (ag__.ld(self), ag__.ld(iterator)), None, fscope)\nValueError: in user code:\n\n    File \"/Users/susiegrigson/opt/anaconda3/envs/phynteny/lib/python3.8/site-packages/keras/engine/training.py\", line 1160, in train_function  *\n        return step_function(self, iterator)\n    File \"/Users/susiegrigson/opt/anaconda3/envs/phynteny/lib/python3.8/site-packages/keras/engine/training.py\", line 1146, in step_function  **\n        outputs = model.distribute_strategy.run(run_step, args=(data,))\n    File \"/Users/susiegrigson/opt/anaconda3/envs/phynteny/lib/python3.8/site-packages/keras/engine/training.py\", line 1135, in run_step  **\n        outputs = model.train_step(data)\n    File \"/Users/susiegrigson/opt/anaconda3/envs/phynteny/lib/python3.8/site-packages/keras/engine/training.py\", line 993, in train_step\n        y_pred = self(x, training=True)\n    File \"/Users/susiegrigson/opt/anaconda3/envs/phynteny/lib/python3.8/site-packages/keras/utils/traceback_utils.py\", line 70, in error_handler\n        raise e.with_traceback(filtered_tb) from None\n    File \"/Users/susiegrigson/opt/anaconda3/envs/phynteny/lib/python3.8/site-packages/keras/engine/input_spec.py\", line 295, in assert_input_compatibility\n        raise ValueError(\n\n    ValueError: Input 0 of layer \"sequential_8\" is incompatible with the layer: expected shape=(None, 1, 1920), found shape=(None, 1920)\n\n\n--------------------------------------------------------------------------------\n1 fits failed with the following error:\nTraceback (most recent call last):\n  File \"/Users/susiegrigson/opt/anaconda3/envs/phynteny/lib/python3.8/site-packages/sklearn/model_selection/_validation.py\", line 686, in _fit_and_score\n    estimator.fit(X_train, y_train, **fit_params)\n  File \"/Users/susiegrigson/opt/anaconda3/envs/phynteny/lib/python3.8/site-packages/scikeras/wrappers.py\", line 1494, in fit\n    super().fit(X=X, y=y, sample_weight=sample_weight, **kwargs)\n  File \"/Users/susiegrigson/opt/anaconda3/envs/phynteny/lib/python3.8/site-packages/scikeras/wrappers.py\", line 762, in fit\n    self._fit(\n  File \"/Users/susiegrigson/opt/anaconda3/envs/phynteny/lib/python3.8/site-packages/scikeras/wrappers.py\", line 931, in _fit\n    self._fit_keras_model(\n  File \"/Users/susiegrigson/opt/anaconda3/envs/phynteny/lib/python3.8/site-packages/scikeras/wrappers.py\", line 526, in _fit_keras_model\n    hist = self.model_.fit(x=X, y=y, **fit_args)\n  File \"/Users/susiegrigson/opt/anaconda3/envs/phynteny/lib/python3.8/site-packages/keras/utils/traceback_utils.py\", line 70, in error_handler\n    raise e.with_traceback(filtered_tb) from None\n  File \"/var/folders/df/d2hn3bdx7dj7syrpbrxgtzkw0000gn/T/__autograph_generated_filenvqcw9qf.py\", line 15, in tf__train_function\n    retval_ = ag__.converted_call(ag__.ld(step_function), (ag__.ld(self), ag__.ld(iterator)), None, fscope)\nValueError: in user code:\n\n    File \"/Users/susiegrigson/opt/anaconda3/envs/phynteny/lib/python3.8/site-packages/keras/engine/training.py\", line 1160, in train_function  *\n        return step_function(self, iterator)\n    File \"/Users/susiegrigson/opt/anaconda3/envs/phynteny/lib/python3.8/site-packages/keras/engine/training.py\", line 1146, in step_function  **\n        outputs = model.distribute_strategy.run(run_step, args=(data,))\n    File \"/Users/susiegrigson/opt/anaconda3/envs/phynteny/lib/python3.8/site-packages/keras/engine/training.py\", line 1135, in run_step  **\n        outputs = model.train_step(data)\n    File \"/Users/susiegrigson/opt/anaconda3/envs/phynteny/lib/python3.8/site-packages/keras/engine/training.py\", line 993, in train_step\n        y_pred = self(x, training=True)\n    File \"/Users/susiegrigson/opt/anaconda3/envs/phynteny/lib/python3.8/site-packages/keras/utils/traceback_utils.py\", line 70, in error_handler\n        raise e.with_traceback(filtered_tb) from None\n    File \"/Users/susiegrigson/opt/anaconda3/envs/phynteny/lib/python3.8/site-packages/keras/engine/input_spec.py\", line 295, in assert_input_compatibility\n        raise ValueError(\n\n    ValueError: Input 0 of layer \"sequential_9\" is incompatible with the layer: expected shape=(None, 1, 1920), found shape=(None, 1920)\n\n\n--------------------------------------------------------------------------------\n1 fits failed with the following error:\nTraceback (most recent call last):\n  File \"/Users/susiegrigson/opt/anaconda3/envs/phynteny/lib/python3.8/site-packages/sklearn/model_selection/_validation.py\", line 686, in _fit_and_score\n    estimator.fit(X_train, y_train, **fit_params)\n  File \"/Users/susiegrigson/opt/anaconda3/envs/phynteny/lib/python3.8/site-packages/scikeras/wrappers.py\", line 1494, in fit\n    super().fit(X=X, y=y, sample_weight=sample_weight, **kwargs)\n  File \"/Users/susiegrigson/opt/anaconda3/envs/phynteny/lib/python3.8/site-packages/scikeras/wrappers.py\", line 762, in fit\n    self._fit(\n  File \"/Users/susiegrigson/opt/anaconda3/envs/phynteny/lib/python3.8/site-packages/scikeras/wrappers.py\", line 931, in _fit\n    self._fit_keras_model(\n  File \"/Users/susiegrigson/opt/anaconda3/envs/phynteny/lib/python3.8/site-packages/scikeras/wrappers.py\", line 526, in _fit_keras_model\n    hist = self.model_.fit(x=X, y=y, **fit_args)\n  File \"/Users/susiegrigson/opt/anaconda3/envs/phynteny/lib/python3.8/site-packages/keras/utils/traceback_utils.py\", line 70, in error_handler\n    raise e.with_traceback(filtered_tb) from None\n  File \"/var/folders/df/d2hn3bdx7dj7syrpbrxgtzkw0000gn/T/__autograph_generated_filext2s2_c4.py\", line 15, in tf__train_function\n    retval_ = ag__.converted_call(ag__.ld(step_function), (ag__.ld(self), ag__.ld(iterator)), None, fscope)\nValueError: in user code:\n\n    File \"/Users/susiegrigson/opt/anaconda3/envs/phynteny/lib/python3.8/site-packages/keras/engine/training.py\", line 1160, in train_function  *\n        return step_function(self, iterator)\n    File \"/Users/susiegrigson/opt/anaconda3/envs/phynteny/lib/python3.8/site-packages/keras/engine/training.py\", line 1146, in step_function  **\n        outputs = model.distribute_strategy.run(run_step, args=(data,))\n    File \"/Users/susiegrigson/opt/anaconda3/envs/phynteny/lib/python3.8/site-packages/keras/engine/training.py\", line 1135, in run_step  **\n        outputs = model.train_step(data)\n    File \"/Users/susiegrigson/opt/anaconda3/envs/phynteny/lib/python3.8/site-packages/keras/engine/training.py\", line 993, in train_step\n        y_pred = self(x, training=True)\n    File \"/Users/susiegrigson/opt/anaconda3/envs/phynteny/lib/python3.8/site-packages/keras/utils/traceback_utils.py\", line 70, in error_handler\n        raise e.with_traceback(filtered_tb) from None\n    File \"/Users/susiegrigson/opt/anaconda3/envs/phynteny/lib/python3.8/site-packages/keras/engine/input_spec.py\", line 295, in assert_input_compatibility\n        raise ValueError(\n\n    ValueError: Input 0 of layer \"sequential_10\" is incompatible with the layer: expected shape=(None, 1, 1920), found shape=(None, 1920)\n\n\n--------------------------------------------------------------------------------\n1 fits failed with the following error:\nTraceback (most recent call last):\n  File \"/Users/susiegrigson/opt/anaconda3/envs/phynteny/lib/python3.8/site-packages/sklearn/model_selection/_validation.py\", line 686, in _fit_and_score\n    estimator.fit(X_train, y_train, **fit_params)\n  File \"/Users/susiegrigson/opt/anaconda3/envs/phynteny/lib/python3.8/site-packages/scikeras/wrappers.py\", line 1494, in fit\n    super().fit(X=X, y=y, sample_weight=sample_weight, **kwargs)\n  File \"/Users/susiegrigson/opt/anaconda3/envs/phynteny/lib/python3.8/site-packages/scikeras/wrappers.py\", line 762, in fit\n    self._fit(\n  File \"/Users/susiegrigson/opt/anaconda3/envs/phynteny/lib/python3.8/site-packages/scikeras/wrappers.py\", line 931, in _fit\n    self._fit_keras_model(\n  File \"/Users/susiegrigson/opt/anaconda3/envs/phynteny/lib/python3.8/site-packages/scikeras/wrappers.py\", line 526, in _fit_keras_model\n    hist = self.model_.fit(x=X, y=y, **fit_args)\n  File \"/Users/susiegrigson/opt/anaconda3/envs/phynteny/lib/python3.8/site-packages/keras/utils/traceback_utils.py\", line 70, in error_handler\n    raise e.with_traceback(filtered_tb) from None\n  File \"/var/folders/df/d2hn3bdx7dj7syrpbrxgtzkw0000gn/T/__autograph_generated_filemelktkna.py\", line 15, in tf__train_function\n    retval_ = ag__.converted_call(ag__.ld(step_function), (ag__.ld(self), ag__.ld(iterator)), None, fscope)\nValueError: in user code:\n\n    File \"/Users/susiegrigson/opt/anaconda3/envs/phynteny/lib/python3.8/site-packages/keras/engine/training.py\", line 1160, in train_function  *\n        return step_function(self, iterator)\n    File \"/Users/susiegrigson/opt/anaconda3/envs/phynteny/lib/python3.8/site-packages/keras/engine/training.py\", line 1146, in step_function  **\n        outputs = model.distribute_strategy.run(run_step, args=(data,))\n    File \"/Users/susiegrigson/opt/anaconda3/envs/phynteny/lib/python3.8/site-packages/keras/engine/training.py\", line 1135, in run_step  **\n        outputs = model.train_step(data)\n    File \"/Users/susiegrigson/opt/anaconda3/envs/phynteny/lib/python3.8/site-packages/keras/engine/training.py\", line 993, in train_step\n        y_pred = self(x, training=True)\n    File \"/Users/susiegrigson/opt/anaconda3/envs/phynteny/lib/python3.8/site-packages/keras/utils/traceback_utils.py\", line 70, in error_handler\n        raise e.with_traceback(filtered_tb) from None\n    File \"/Users/susiegrigson/opt/anaconda3/envs/phynteny/lib/python3.8/site-packages/keras/engine/input_spec.py\", line 295, in assert_input_compatibility\n        raise ValueError(\n\n    ValueError: Input 0 of layer \"sequential_9\" is incompatible with the layer: expected shape=(None, 1, 1920), found shape=(None, 1920)\n\n\n--------------------------------------------------------------------------------\n1 fits failed with the following error:\nTraceback (most recent call last):\n  File \"/Users/susiegrigson/opt/anaconda3/envs/phynteny/lib/python3.8/site-packages/sklearn/model_selection/_validation.py\", line 686, in _fit_and_score\n    estimator.fit(X_train, y_train, **fit_params)\n  File \"/Users/susiegrigson/opt/anaconda3/envs/phynteny/lib/python3.8/site-packages/scikeras/wrappers.py\", line 1494, in fit\n    super().fit(X=X, y=y, sample_weight=sample_weight, **kwargs)\n  File \"/Users/susiegrigson/opt/anaconda3/envs/phynteny/lib/python3.8/site-packages/scikeras/wrappers.py\", line 762, in fit\n    self._fit(\n  File \"/Users/susiegrigson/opt/anaconda3/envs/phynteny/lib/python3.8/site-packages/scikeras/wrappers.py\", line 931, in _fit\n    self._fit_keras_model(\n  File \"/Users/susiegrigson/opt/anaconda3/envs/phynteny/lib/python3.8/site-packages/scikeras/wrappers.py\", line 526, in _fit_keras_model\n    hist = self.model_.fit(x=X, y=y, **fit_args)\n  File \"/Users/susiegrigson/opt/anaconda3/envs/phynteny/lib/python3.8/site-packages/keras/utils/traceback_utils.py\", line 70, in error_handler\n    raise e.with_traceback(filtered_tb) from None\n  File \"/var/folders/df/d2hn3bdx7dj7syrpbrxgtzkw0000gn/T/__autograph_generated_filepgzqv3j0.py\", line 15, in tf__train_function\n    retval_ = ag__.converted_call(ag__.ld(step_function), (ag__.ld(self), ag__.ld(iterator)), None, fscope)\nValueError: in user code:\n\n    File \"/Users/susiegrigson/opt/anaconda3/envs/phynteny/lib/python3.8/site-packages/keras/engine/training.py\", line 1160, in train_function  *\n        return step_function(self, iterator)\n    File \"/Users/susiegrigson/opt/anaconda3/envs/phynteny/lib/python3.8/site-packages/keras/engine/training.py\", line 1146, in step_function  **\n        outputs = model.distribute_strategy.run(run_step, args=(data,))\n    File \"/Users/susiegrigson/opt/anaconda3/envs/phynteny/lib/python3.8/site-packages/keras/engine/training.py\", line 1135, in run_step  **\n        outputs = model.train_step(data)\n    File \"/Users/susiegrigson/opt/anaconda3/envs/phynteny/lib/python3.8/site-packages/keras/engine/training.py\", line 993, in train_step\n        y_pred = self(x, training=True)\n    File \"/Users/susiegrigson/opt/anaconda3/envs/phynteny/lib/python3.8/site-packages/keras/utils/traceback_utils.py\", line 70, in error_handler\n        raise e.with_traceback(filtered_tb) from None\n    File \"/Users/susiegrigson/opt/anaconda3/envs/phynteny/lib/python3.8/site-packages/keras/engine/input_spec.py\", line 295, in assert_input_compatibility\n        raise ValueError(\n\n    ValueError: Input 0 of layer \"sequential_9\" is incompatible with the layer: expected shape=(None, 1, 1920), found shape=(None, 1920)\n\n\n--------------------------------------------------------------------------------\n1 fits failed with the following error:\nTraceback (most recent call last):\n  File \"/Users/susiegrigson/opt/anaconda3/envs/phynteny/lib/python3.8/site-packages/sklearn/model_selection/_validation.py\", line 686, in _fit_and_score\n    estimator.fit(X_train, y_train, **fit_params)\n  File \"/Users/susiegrigson/opt/anaconda3/envs/phynteny/lib/python3.8/site-packages/scikeras/wrappers.py\", line 1494, in fit\n    super().fit(X=X, y=y, sample_weight=sample_weight, **kwargs)\n  File \"/Users/susiegrigson/opt/anaconda3/envs/phynteny/lib/python3.8/site-packages/scikeras/wrappers.py\", line 762, in fit\n    self._fit(\n  File \"/Users/susiegrigson/opt/anaconda3/envs/phynteny/lib/python3.8/site-packages/scikeras/wrappers.py\", line 931, in _fit\n    self._fit_keras_model(\n  File \"/Users/susiegrigson/opt/anaconda3/envs/phynteny/lib/python3.8/site-packages/scikeras/wrappers.py\", line 526, in _fit_keras_model\n    hist = self.model_.fit(x=X, y=y, **fit_args)\n  File \"/Users/susiegrigson/opt/anaconda3/envs/phynteny/lib/python3.8/site-packages/keras/utils/traceback_utils.py\", line 70, in error_handler\n    raise e.with_traceback(filtered_tb) from None\n  File \"/var/folders/df/d2hn3bdx7dj7syrpbrxgtzkw0000gn/T/__autograph_generated_fileusdxkgvw.py\", line 15, in tf__train_function\n    retval_ = ag__.converted_call(ag__.ld(step_function), (ag__.ld(self), ag__.ld(iterator)), None, fscope)\nValueError: in user code:\n\n    File \"/Users/susiegrigson/opt/anaconda3/envs/phynteny/lib/python3.8/site-packages/keras/engine/training.py\", line 1160, in train_function  *\n        return step_function(self, iterator)\n    File \"/Users/susiegrigson/opt/anaconda3/envs/phynteny/lib/python3.8/site-packages/keras/engine/training.py\", line 1146, in step_function  **\n        outputs = model.distribute_strategy.run(run_step, args=(data,))\n    File \"/Users/susiegrigson/opt/anaconda3/envs/phynteny/lib/python3.8/site-packages/keras/engine/training.py\", line 1135, in run_step  **\n        outputs = model.train_step(data)\n    File \"/Users/susiegrigson/opt/anaconda3/envs/phynteny/lib/python3.8/site-packages/keras/engine/training.py\", line 993, in train_step\n        y_pred = self(x, training=True)\n    File \"/Users/susiegrigson/opt/anaconda3/envs/phynteny/lib/python3.8/site-packages/keras/utils/traceback_utils.py\", line 70, in error_handler\n        raise e.with_traceback(filtered_tb) from None\n    File \"/Users/susiegrigson/opt/anaconda3/envs/phynteny/lib/python3.8/site-packages/keras/engine/input_spec.py\", line 295, in assert_input_compatibility\n        raise ValueError(\n\n    ValueError: Input 0 of layer \"sequential_9\" is incompatible with the layer: expected shape=(None, 1, 1920), found shape=(None, 1920)\n\n\n--------------------------------------------------------------------------------\n1 fits failed with the following error:\nTraceback (most recent call last):\n  File \"/Users/susiegrigson/opt/anaconda3/envs/phynteny/lib/python3.8/site-packages/sklearn/model_selection/_validation.py\", line 686, in _fit_and_score\n    estimator.fit(X_train, y_train, **fit_params)\n  File \"/Users/susiegrigson/opt/anaconda3/envs/phynteny/lib/python3.8/site-packages/scikeras/wrappers.py\", line 1494, in fit\n    super().fit(X=X, y=y, sample_weight=sample_weight, **kwargs)\n  File \"/Users/susiegrigson/opt/anaconda3/envs/phynteny/lib/python3.8/site-packages/scikeras/wrappers.py\", line 762, in fit\n    self._fit(\n  File \"/Users/susiegrigson/opt/anaconda3/envs/phynteny/lib/python3.8/site-packages/scikeras/wrappers.py\", line 931, in _fit\n    self._fit_keras_model(\n  File \"/Users/susiegrigson/opt/anaconda3/envs/phynteny/lib/python3.8/site-packages/scikeras/wrappers.py\", line 526, in _fit_keras_model\n    hist = self.model_.fit(x=X, y=y, **fit_args)\n  File \"/Users/susiegrigson/opt/anaconda3/envs/phynteny/lib/python3.8/site-packages/keras/utils/traceback_utils.py\", line 70, in error_handler\n    raise e.with_traceback(filtered_tb) from None\n  File \"/var/folders/df/d2hn3bdx7dj7syrpbrxgtzkw0000gn/T/__autograph_generated_filej5ika9tg.py\", line 15, in tf__train_function\n    retval_ = ag__.converted_call(ag__.ld(step_function), (ag__.ld(self), ag__.ld(iterator)), None, fscope)\nValueError: in user code:\n\n    File \"/Users/susiegrigson/opt/anaconda3/envs/phynteny/lib/python3.8/site-packages/keras/engine/training.py\", line 1160, in train_function  *\n        return step_function(self, iterator)\n    File \"/Users/susiegrigson/opt/anaconda3/envs/phynteny/lib/python3.8/site-packages/keras/engine/training.py\", line 1146, in step_function  **\n        outputs = model.distribute_strategy.run(run_step, args=(data,))\n    File \"/Users/susiegrigson/opt/anaconda3/envs/phynteny/lib/python3.8/site-packages/keras/engine/training.py\", line 1135, in run_step  **\n        outputs = model.train_step(data)\n    File \"/Users/susiegrigson/opt/anaconda3/envs/phynteny/lib/python3.8/site-packages/keras/engine/training.py\", line 993, in train_step\n        y_pred = self(x, training=True)\n    File \"/Users/susiegrigson/opt/anaconda3/envs/phynteny/lib/python3.8/site-packages/keras/utils/traceback_utils.py\", line 70, in error_handler\n        raise e.with_traceback(filtered_tb) from None\n    File \"/Users/susiegrigson/opt/anaconda3/envs/phynteny/lib/python3.8/site-packages/keras/engine/input_spec.py\", line 295, in assert_input_compatibility\n        raise ValueError(\n\n    ValueError: Input 0 of layer \"sequential_10\" is incompatible with the layer: expected shape=(None, 1, 1920), found shape=(None, 1920)\n\n\n--------------------------------------------------------------------------------\n1 fits failed with the following error:\nTraceback (most recent call last):\n  File \"/Users/susiegrigson/opt/anaconda3/envs/phynteny/lib/python3.8/site-packages/sklearn/model_selection/_validation.py\", line 686, in _fit_and_score\n    estimator.fit(X_train, y_train, **fit_params)\n  File \"/Users/susiegrigson/opt/anaconda3/envs/phynteny/lib/python3.8/site-packages/scikeras/wrappers.py\", line 1494, in fit\n    super().fit(X=X, y=y, sample_weight=sample_weight, **kwargs)\n  File \"/Users/susiegrigson/opt/anaconda3/envs/phynteny/lib/python3.8/site-packages/scikeras/wrappers.py\", line 762, in fit\n    self._fit(\n  File \"/Users/susiegrigson/opt/anaconda3/envs/phynteny/lib/python3.8/site-packages/scikeras/wrappers.py\", line 931, in _fit\n    self._fit_keras_model(\n  File \"/Users/susiegrigson/opt/anaconda3/envs/phynteny/lib/python3.8/site-packages/scikeras/wrappers.py\", line 526, in _fit_keras_model\n    hist = self.model_.fit(x=X, y=y, **fit_args)\n  File \"/Users/susiegrigson/opt/anaconda3/envs/phynteny/lib/python3.8/site-packages/keras/utils/traceback_utils.py\", line 70, in error_handler\n    raise e.with_traceback(filtered_tb) from None\n  File \"/var/folders/df/d2hn3bdx7dj7syrpbrxgtzkw0000gn/T/__autograph_generated_fileuin_5wmx.py\", line 15, in tf__train_function\n    retval_ = ag__.converted_call(ag__.ld(step_function), (ag__.ld(self), ag__.ld(iterator)), None, fscope)\nValueError: in user code:\n\n    File \"/Users/susiegrigson/opt/anaconda3/envs/phynteny/lib/python3.8/site-packages/keras/engine/training.py\", line 1160, in train_function  *\n        return step_function(self, iterator)\n    File \"/Users/susiegrigson/opt/anaconda3/envs/phynteny/lib/python3.8/site-packages/keras/engine/training.py\", line 1146, in step_function  **\n        outputs = model.distribute_strategy.run(run_step, args=(data,))\n    File \"/Users/susiegrigson/opt/anaconda3/envs/phynteny/lib/python3.8/site-packages/keras/engine/training.py\", line 1135, in run_step  **\n        outputs = model.train_step(data)\n    File \"/Users/susiegrigson/opt/anaconda3/envs/phynteny/lib/python3.8/site-packages/keras/engine/training.py\", line 993, in train_step\n        y_pred = self(x, training=True)\n    File \"/Users/susiegrigson/opt/anaconda3/envs/phynteny/lib/python3.8/site-packages/keras/utils/traceback_utils.py\", line 70, in error_handler\n        raise e.with_traceback(filtered_tb) from None\n    File \"/Users/susiegrigson/opt/anaconda3/envs/phynteny/lib/python3.8/site-packages/keras/engine/input_spec.py\", line 295, in assert_input_compatibility\n        raise ValueError(\n\n    ValueError: Input 0 of layer \"sequential_9\" is incompatible with the layer: expected shape=(None, 1, 1920), found shape=(None, 1920)\n\n\n--------------------------------------------------------------------------------\n1 fits failed with the following error:\nTraceback (most recent call last):\n  File \"/Users/susiegrigson/opt/anaconda3/envs/phynteny/lib/python3.8/site-packages/sklearn/model_selection/_validation.py\", line 686, in _fit_and_score\n    estimator.fit(X_train, y_train, **fit_params)\n  File \"/Users/susiegrigson/opt/anaconda3/envs/phynteny/lib/python3.8/site-packages/scikeras/wrappers.py\", line 1494, in fit\n    super().fit(X=X, y=y, sample_weight=sample_weight, **kwargs)\n  File \"/Users/susiegrigson/opt/anaconda3/envs/phynteny/lib/python3.8/site-packages/scikeras/wrappers.py\", line 762, in fit\n    self._fit(\n  File \"/Users/susiegrigson/opt/anaconda3/envs/phynteny/lib/python3.8/site-packages/scikeras/wrappers.py\", line 931, in _fit\n    self._fit_keras_model(\n  File \"/Users/susiegrigson/opt/anaconda3/envs/phynteny/lib/python3.8/site-packages/scikeras/wrappers.py\", line 526, in _fit_keras_model\n    hist = self.model_.fit(x=X, y=y, **fit_args)\n  File \"/Users/susiegrigson/opt/anaconda3/envs/phynteny/lib/python3.8/site-packages/keras/utils/traceback_utils.py\", line 70, in error_handler\n    raise e.with_traceback(filtered_tb) from None\n  File \"/var/folders/df/d2hn3bdx7dj7syrpbrxgtzkw0000gn/T/__autograph_generated_fileql9ao1yw.py\", line 15, in tf__train_function\n    retval_ = ag__.converted_call(ag__.ld(step_function), (ag__.ld(self), ag__.ld(iterator)), None, fscope)\nValueError: in user code:\n\n    File \"/Users/susiegrigson/opt/anaconda3/envs/phynteny/lib/python3.8/site-packages/keras/engine/training.py\", line 1160, in train_function  *\n        return step_function(self, iterator)\n    File \"/Users/susiegrigson/opt/anaconda3/envs/phynteny/lib/python3.8/site-packages/keras/engine/training.py\", line 1146, in step_function  **\n        outputs = model.distribute_strategy.run(run_step, args=(data,))\n    File \"/Users/susiegrigson/opt/anaconda3/envs/phynteny/lib/python3.8/site-packages/keras/engine/training.py\", line 1135, in run_step  **\n        outputs = model.train_step(data)\n    File \"/Users/susiegrigson/opt/anaconda3/envs/phynteny/lib/python3.8/site-packages/keras/engine/training.py\", line 993, in train_step\n        y_pred = self(x, training=True)\n    File \"/Users/susiegrigson/opt/anaconda3/envs/phynteny/lib/python3.8/site-packages/keras/utils/traceback_utils.py\", line 70, in error_handler\n        raise e.with_traceback(filtered_tb) from None\n    File \"/Users/susiegrigson/opt/anaconda3/envs/phynteny/lib/python3.8/site-packages/keras/engine/input_spec.py\", line 295, in assert_input_compatibility\n        raise ValueError(\n\n    ValueError: Input 0 of layer \"sequential_10\" is incompatible with the layer: expected shape=(None, 1, 1920), found shape=(None, 1920)\n\n\n--------------------------------------------------------------------------------\n1 fits failed with the following error:\nTraceback (most recent call last):\n  File \"/Users/susiegrigson/opt/anaconda3/envs/phynteny/lib/python3.8/site-packages/sklearn/model_selection/_validation.py\", line 686, in _fit_and_score\n    estimator.fit(X_train, y_train, **fit_params)\n  File \"/Users/susiegrigson/opt/anaconda3/envs/phynteny/lib/python3.8/site-packages/scikeras/wrappers.py\", line 1494, in fit\n    super().fit(X=X, y=y, sample_weight=sample_weight, **kwargs)\n  File \"/Users/susiegrigson/opt/anaconda3/envs/phynteny/lib/python3.8/site-packages/scikeras/wrappers.py\", line 762, in fit\n    self._fit(\n  File \"/Users/susiegrigson/opt/anaconda3/envs/phynteny/lib/python3.8/site-packages/scikeras/wrappers.py\", line 931, in _fit\n    self._fit_keras_model(\n  File \"/Users/susiegrigson/opt/anaconda3/envs/phynteny/lib/python3.8/site-packages/scikeras/wrappers.py\", line 526, in _fit_keras_model\n    hist = self.model_.fit(x=X, y=y, **fit_args)\n  File \"/Users/susiegrigson/opt/anaconda3/envs/phynteny/lib/python3.8/site-packages/keras/utils/traceback_utils.py\", line 70, in error_handler\n    raise e.with_traceback(filtered_tb) from None\n  File \"/var/folders/df/d2hn3bdx7dj7syrpbrxgtzkw0000gn/T/__autograph_generated_filext2s2_c4.py\", line 15, in tf__train_function\n    retval_ = ag__.converted_call(ag__.ld(step_function), (ag__.ld(self), ag__.ld(iterator)), None, fscope)\nValueError: in user code:\n\n    File \"/Users/susiegrigson/opt/anaconda3/envs/phynteny/lib/python3.8/site-packages/keras/engine/training.py\", line 1160, in train_function  *\n        return step_function(self, iterator)\n    File \"/Users/susiegrigson/opt/anaconda3/envs/phynteny/lib/python3.8/site-packages/keras/engine/training.py\", line 1146, in step_function  **\n        outputs = model.distribute_strategy.run(run_step, args=(data,))\n    File \"/Users/susiegrigson/opt/anaconda3/envs/phynteny/lib/python3.8/site-packages/keras/engine/training.py\", line 1135, in run_step  **\n        outputs = model.train_step(data)\n    File \"/Users/susiegrigson/opt/anaconda3/envs/phynteny/lib/python3.8/site-packages/keras/engine/training.py\", line 993, in train_step\n        y_pred = self(x, training=True)\n    File \"/Users/susiegrigson/opt/anaconda3/envs/phynteny/lib/python3.8/site-packages/keras/utils/traceback_utils.py\", line 70, in error_handler\n        raise e.with_traceback(filtered_tb) from None\n    File \"/Users/susiegrigson/opt/anaconda3/envs/phynteny/lib/python3.8/site-packages/keras/engine/input_spec.py\", line 295, in assert_input_compatibility\n        raise ValueError(\n\n    ValueError: Input 0 of layer \"sequential_11\" is incompatible with the layer: expected shape=(None, 1, 1920), found shape=(None, 1920)\n\n\n--------------------------------------------------------------------------------\n1 fits failed with the following error:\nTraceback (most recent call last):\n  File \"/Users/susiegrigson/opt/anaconda3/envs/phynteny/lib/python3.8/site-packages/sklearn/model_selection/_validation.py\", line 686, in _fit_and_score\n    estimator.fit(X_train, y_train, **fit_params)\n  File \"/Users/susiegrigson/opt/anaconda3/envs/phynteny/lib/python3.8/site-packages/scikeras/wrappers.py\", line 1494, in fit\n    super().fit(X=X, y=y, sample_weight=sample_weight, **kwargs)\n  File \"/Users/susiegrigson/opt/anaconda3/envs/phynteny/lib/python3.8/site-packages/scikeras/wrappers.py\", line 762, in fit\n    self._fit(\n  File \"/Users/susiegrigson/opt/anaconda3/envs/phynteny/lib/python3.8/site-packages/scikeras/wrappers.py\", line 931, in _fit\n    self._fit_keras_model(\n  File \"/Users/susiegrigson/opt/anaconda3/envs/phynteny/lib/python3.8/site-packages/scikeras/wrappers.py\", line 526, in _fit_keras_model\n    hist = self.model_.fit(x=X, y=y, **fit_args)\n  File \"/Users/susiegrigson/opt/anaconda3/envs/phynteny/lib/python3.8/site-packages/keras/utils/traceback_utils.py\", line 70, in error_handler\n    raise e.with_traceback(filtered_tb) from None\n  File \"/var/folders/df/d2hn3bdx7dj7syrpbrxgtzkw0000gn/T/__autograph_generated_filepgzqv3j0.py\", line 15, in tf__train_function\n    retval_ = ag__.converted_call(ag__.ld(step_function), (ag__.ld(self), ag__.ld(iterator)), None, fscope)\nValueError: in user code:\n\n    File \"/Users/susiegrigson/opt/anaconda3/envs/phynteny/lib/python3.8/site-packages/keras/engine/training.py\", line 1160, in train_function  *\n        return step_function(self, iterator)\n    File \"/Users/susiegrigson/opt/anaconda3/envs/phynteny/lib/python3.8/site-packages/keras/engine/training.py\", line 1146, in step_function  **\n        outputs = model.distribute_strategy.run(run_step, args=(data,))\n    File \"/Users/susiegrigson/opt/anaconda3/envs/phynteny/lib/python3.8/site-packages/keras/engine/training.py\", line 1135, in run_step  **\n        outputs = model.train_step(data)\n    File \"/Users/susiegrigson/opt/anaconda3/envs/phynteny/lib/python3.8/site-packages/keras/engine/training.py\", line 993, in train_step\n        y_pred = self(x, training=True)\n    File \"/Users/susiegrigson/opt/anaconda3/envs/phynteny/lib/python3.8/site-packages/keras/utils/traceback_utils.py\", line 70, in error_handler\n        raise e.with_traceback(filtered_tb) from None\n    File \"/Users/susiegrigson/opt/anaconda3/envs/phynteny/lib/python3.8/site-packages/keras/engine/input_spec.py\", line 295, in assert_input_compatibility\n        raise ValueError(\n\n    ValueError: Input 0 of layer \"sequential_10\" is incompatible with the layer: expected shape=(None, 1, 1920), found shape=(None, 1920)\n\n",
     "output_type": "error",
     "traceback": [
      "\u001B[0;31m---------------------------------------------------------------------------\u001B[0m",
      "\u001B[0;31mValueError\u001B[0m                                Traceback (most recent call last)",
      "\u001B[0;32m<ipython-input-106-c51881ca602c>\u001B[0m in \u001B[0;36m<module>\u001B[0;34m\u001B[0m\n\u001B[0;32m----> 1\u001B[0;31m \u001B[0mtrain_model\u001B[0m\u001B[0;34m.\u001B[0m\u001B[0mperform_search\u001B[0m\u001B[0;34m(\u001B[0m\u001B[0mX\u001B[0m\u001B[0;34m,\u001B[0m\u001B[0my\u001B[0m\u001B[0;34m)\u001B[0m\u001B[0;34m\u001B[0m\u001B[0;34m\u001B[0m\u001B[0m\n\u001B[0m",
      "\u001B[0;32m~/PycharmProjects/Phynteny/phynteny_utils/train_model.py\u001B[0m in \u001B[0;36mperform_search\u001B[0;34m(X, y)\u001B[0m\n\u001B[1;32m    101\u001B[0m     \u001B[0;31m#print(y.shape)\u001B[0m\u001B[0;34m\u001B[0m\u001B[0;34m\u001B[0m\u001B[0;34m\u001B[0m\u001B[0m\n\u001B[1;32m    102\u001B[0m \u001B[0;34m\u001B[0m\u001B[0m\n\u001B[0;32m--> 103\u001B[0;31m     \u001B[0msearch_result\u001B[0m \u001B[0;34m=\u001B[0m \u001B[0msearch\u001B[0m\u001B[0;34m.\u001B[0m\u001B[0mfit\u001B[0m\u001B[0;34m(\u001B[0m\u001B[0mX\u001B[0m\u001B[0;34m,\u001B[0m \u001B[0my\u001B[0m\u001B[0;34m)\u001B[0m\u001B[0;34m\u001B[0m\u001B[0;34m\u001B[0m\u001B[0m\n\u001B[0m\u001B[1;32m    104\u001B[0m \u001B[0;34m\u001B[0m\u001B[0m\n\u001B[1;32m    105\u001B[0m     \u001B[0;31m# evaluate the results of the grid search\u001B[0m\u001B[0;34m\u001B[0m\u001B[0;34m\u001B[0m\u001B[0;34m\u001B[0m\u001B[0m\n",
      "\u001B[0;32m~/opt/anaconda3/envs/phynteny/lib/python3.8/site-packages/sklearn/model_selection/_search.py\u001B[0m in \u001B[0;36mfit\u001B[0;34m(self, X, y, groups, **fit_params)\u001B[0m\n\u001B[1;32m    872\u001B[0m                 \u001B[0;32mreturn\u001B[0m \u001B[0mresults\u001B[0m\u001B[0;34m\u001B[0m\u001B[0;34m\u001B[0m\u001B[0m\n\u001B[1;32m    873\u001B[0m \u001B[0;34m\u001B[0m\u001B[0m\n\u001B[0;32m--> 874\u001B[0;31m             \u001B[0mself\u001B[0m\u001B[0;34m.\u001B[0m\u001B[0m_run_search\u001B[0m\u001B[0;34m(\u001B[0m\u001B[0mevaluate_candidates\u001B[0m\u001B[0;34m)\u001B[0m\u001B[0;34m\u001B[0m\u001B[0;34m\u001B[0m\u001B[0m\n\u001B[0m\u001B[1;32m    875\u001B[0m \u001B[0;34m\u001B[0m\u001B[0m\n\u001B[1;32m    876\u001B[0m             \u001B[0;31m# multimetric is determined here because in the case of a callable\u001B[0m\u001B[0;34m\u001B[0m\u001B[0;34m\u001B[0m\u001B[0;34m\u001B[0m\u001B[0m\n",
      "\u001B[0;32m~/opt/anaconda3/envs/phynteny/lib/python3.8/site-packages/sklearn/model_selection/_search.py\u001B[0m in \u001B[0;36m_run_search\u001B[0;34m(self, evaluate_candidates)\u001B[0m\n\u001B[1;32m   1386\u001B[0m     \u001B[0;32mdef\u001B[0m \u001B[0m_run_search\u001B[0m\u001B[0;34m(\u001B[0m\u001B[0mself\u001B[0m\u001B[0;34m,\u001B[0m \u001B[0mevaluate_candidates\u001B[0m\u001B[0;34m)\u001B[0m\u001B[0;34m:\u001B[0m\u001B[0;34m\u001B[0m\u001B[0;34m\u001B[0m\u001B[0m\n\u001B[1;32m   1387\u001B[0m         \u001B[0;34m\"\"\"Search all candidates in param_grid\"\"\"\u001B[0m\u001B[0;34m\u001B[0m\u001B[0;34m\u001B[0m\u001B[0m\n\u001B[0;32m-> 1388\u001B[0;31m         \u001B[0mevaluate_candidates\u001B[0m\u001B[0;34m(\u001B[0m\u001B[0mParameterGrid\u001B[0m\u001B[0;34m(\u001B[0m\u001B[0mself\u001B[0m\u001B[0;34m.\u001B[0m\u001B[0mparam_grid\u001B[0m\u001B[0;34m)\u001B[0m\u001B[0;34m)\u001B[0m\u001B[0;34m\u001B[0m\u001B[0;34m\u001B[0m\u001B[0m\n\u001B[0m\u001B[1;32m   1389\u001B[0m \u001B[0;34m\u001B[0m\u001B[0m\n\u001B[1;32m   1390\u001B[0m \u001B[0;34m\u001B[0m\u001B[0m\n",
      "\u001B[0;32m~/opt/anaconda3/envs/phynteny/lib/python3.8/site-packages/sklearn/model_selection/_search.py\u001B[0m in \u001B[0;36mevaluate_candidates\u001B[0;34m(candidate_params, cv, more_results)\u001B[0m\n\u001B[1;32m    849\u001B[0m                     )\n\u001B[1;32m    850\u001B[0m \u001B[0;34m\u001B[0m\u001B[0m\n\u001B[0;32m--> 851\u001B[0;31m                 \u001B[0m_warn_or_raise_about_fit_failures\u001B[0m\u001B[0;34m(\u001B[0m\u001B[0mout\u001B[0m\u001B[0;34m,\u001B[0m \u001B[0mself\u001B[0m\u001B[0;34m.\u001B[0m\u001B[0merror_score\u001B[0m\u001B[0;34m)\u001B[0m\u001B[0;34m\u001B[0m\u001B[0;34m\u001B[0m\u001B[0m\n\u001B[0m\u001B[1;32m    852\u001B[0m \u001B[0;34m\u001B[0m\u001B[0m\n\u001B[1;32m    853\u001B[0m                 \u001B[0;31m# For callable self.scoring, the return type is only know after\u001B[0m\u001B[0;34m\u001B[0m\u001B[0;34m\u001B[0m\u001B[0;34m\u001B[0m\u001B[0m\n",
      "\u001B[0;32m~/opt/anaconda3/envs/phynteny/lib/python3.8/site-packages/sklearn/model_selection/_validation.py\u001B[0m in \u001B[0;36m_warn_or_raise_about_fit_failures\u001B[0;34m(results, error_score)\u001B[0m\n\u001B[1;32m    365\u001B[0m                 \u001B[0;34mf\"Below are more details about the failures:\\n{fit_errors_summary}\"\u001B[0m\u001B[0;34m\u001B[0m\u001B[0;34m\u001B[0m\u001B[0m\n\u001B[1;32m    366\u001B[0m             )\n\u001B[0;32m--> 367\u001B[0;31m             \u001B[0;32mraise\u001B[0m \u001B[0mValueError\u001B[0m\u001B[0;34m(\u001B[0m\u001B[0mall_fits_failed_message\u001B[0m\u001B[0;34m)\u001B[0m\u001B[0;34m\u001B[0m\u001B[0;34m\u001B[0m\u001B[0m\n\u001B[0m\u001B[1;32m    368\u001B[0m \u001B[0;34m\u001B[0m\u001B[0m\n\u001B[1;32m    369\u001B[0m         \u001B[0;32melse\u001B[0m\u001B[0;34m:\u001B[0m\u001B[0;34m\u001B[0m\u001B[0;34m\u001B[0m\u001B[0m\n",
      "\u001B[0;31mValueError\u001B[0m: \nAll the 15 fits failed.\nIt is very likely that your model is misconfigured.\nYou can try to debug the error by setting error_score='raise'.\n\nBelow are more details about the failures:\n--------------------------------------------------------------------------------\n1 fits failed with the following error:\nTraceback (most recent call last):\n  File \"/Users/susiegrigson/opt/anaconda3/envs/phynteny/lib/python3.8/site-packages/sklearn/model_selection/_validation.py\", line 686, in _fit_and_score\n    estimator.fit(X_train, y_train, **fit_params)\n  File \"/Users/susiegrigson/opt/anaconda3/envs/phynteny/lib/python3.8/site-packages/scikeras/wrappers.py\", line 1494, in fit\n    super().fit(X=X, y=y, sample_weight=sample_weight, **kwargs)\n  File \"/Users/susiegrigson/opt/anaconda3/envs/phynteny/lib/python3.8/site-packages/scikeras/wrappers.py\", line 762, in fit\n    self._fit(\n  File \"/Users/susiegrigson/opt/anaconda3/envs/phynteny/lib/python3.8/site-packages/scikeras/wrappers.py\", line 931, in _fit\n    self._fit_keras_model(\n  File \"/Users/susiegrigson/opt/anaconda3/envs/phynteny/lib/python3.8/site-packages/scikeras/wrappers.py\", line 526, in _fit_keras_model\n    hist = self.model_.fit(x=X, y=y, **fit_args)\n  File \"/Users/susiegrigson/opt/anaconda3/envs/phynteny/lib/python3.8/site-packages/keras/utils/traceback_utils.py\", line 70, in error_handler\n    raise e.with_traceback(filtered_tb) from None\n  File \"/var/folders/df/d2hn3bdx7dj7syrpbrxgtzkw0000gn/T/__autograph_generated_fileql9ao1yw.py\", line 15, in tf__train_function\n    retval_ = ag__.converted_call(ag__.ld(step_function), (ag__.ld(self), ag__.ld(iterator)), None, fscope)\nValueError: in user code:\n\n    File \"/Users/susiegrigson/opt/anaconda3/envs/phynteny/lib/python3.8/site-packages/keras/engine/training.py\", line 1160, in train_function  *\n        return step_function(self, iterator)\n    File \"/Users/susiegrigson/opt/anaconda3/envs/phynteny/lib/python3.8/site-packages/keras/engine/training.py\", line 1146, in step_function  **\n        outputs = model.distribute_strategy.run(run_step, args=(data,))\n    File \"/Users/susiegrigson/opt/anaconda3/envs/phynteny/lib/python3.8/site-packages/keras/engine/training.py\", line 1135, in run_step  **\n        outputs = model.train_step(data)\n    File \"/Users/susiegrigson/opt/anaconda3/envs/phynteny/lib/python3.8/site-packages/keras/engine/training.py\", line 993, in train_step\n        y_pred = self(x, training=True)\n    File \"/Users/susiegrigson/opt/anaconda3/envs/phynteny/lib/python3.8/site-packages/keras/utils/traceback_utils.py\", line 70, in error_handler\n        raise e.with_traceback(filtered_tb) from None\n    File \"/Users/susiegrigson/opt/anaconda3/envs/phynteny/lib/python3.8/site-packages/keras/engine/input_spec.py\", line 295, in assert_input_compatibility\n        raise ValueError(\n\n    ValueError: Input 0 of layer \"sequential_9\" is incompatible with the layer: expected shape=(None, 1, 1920), found shape=(None, 1920)\n\n\n--------------------------------------------------------------------------------\n1 fits failed with the following error:\nTraceback (most recent call last):\n  File \"/Users/susiegrigson/opt/anaconda3/envs/phynteny/lib/python3.8/site-packages/sklearn/model_selection/_validation.py\", line 686, in _fit_and_score\n    estimator.fit(X_train, y_train, **fit_params)\n  File \"/Users/susiegrigson/opt/anaconda3/envs/phynteny/lib/python3.8/site-packages/scikeras/wrappers.py\", line 1494, in fit\n    super().fit(X=X, y=y, sample_weight=sample_weight, **kwargs)\n  File \"/Users/susiegrigson/opt/anaconda3/envs/phynteny/lib/python3.8/site-packages/scikeras/wrappers.py\", line 762, in fit\n    self._fit(\n  File \"/Users/susiegrigson/opt/anaconda3/envs/phynteny/lib/python3.8/site-packages/scikeras/wrappers.py\", line 931, in _fit\n    self._fit_keras_model(\n  File \"/Users/susiegrigson/opt/anaconda3/envs/phynteny/lib/python3.8/site-packages/scikeras/wrappers.py\", line 526, in _fit_keras_model\n    hist = self.model_.fit(x=X, y=y, **fit_args)\n  File \"/Users/susiegrigson/opt/anaconda3/envs/phynteny/lib/python3.8/site-packages/keras/utils/traceback_utils.py\", line 70, in error_handler\n    raise e.with_traceback(filtered_tb) from None\n  File \"/var/folders/df/d2hn3bdx7dj7syrpbrxgtzkw0000gn/T/__autograph_generated_filej5ika9tg.py\", line 15, in tf__train_function\n    retval_ = ag__.converted_call(ag__.ld(step_function), (ag__.ld(self), ag__.ld(iterator)), None, fscope)\nValueError: in user code:\n\n    File \"/Users/susiegrigson/opt/anaconda3/envs/phynteny/lib/python3.8/site-packages/keras/engine/training.py\", line 1160, in train_function  *\n        return step_function(self, iterator)\n    File \"/Users/susiegrigson/opt/anaconda3/envs/phynteny/lib/python3.8/site-packages/keras/engine/training.py\", line 1146, in step_function  **\n        outputs = model.distribute_strategy.run(run_step, args=(data,))\n    File \"/Users/susiegrigson/opt/anaconda3/envs/phynteny/lib/python3.8/site-packages/keras/engine/training.py\", line 1135, in run_step  **\n        outputs = model.train_step(data)\n    File \"/Users/susiegrigson/opt/anaconda3/envs/phynteny/lib/python3.8/site-packages/keras/engine/training.py\", line 993, in train_step\n        y_pred = self(x, training=True)\n    File \"/Users/susiegrigson/opt/anaconda3/envs/phynteny/lib/python3.8/site-packages/keras/utils/traceback_utils.py\", line 70, in error_handler\n        raise e.with_traceback(filtered_tb) from None\n    File \"/Users/susiegrigson/opt/anaconda3/envs/phynteny/lib/python3.8/site-packages/keras/engine/input_spec.py\", line 295, in assert_input_compatibility\n        raise ValueError(\n\n    ValueError: Input 0 of layer \"sequential_9\" is incompatible with the layer: expected shape=(None, 1, 1920), found shape=(None, 1920)\n\n\n--------------------------------------------------------------------------------\n1 fits failed with the following error:\nTraceback (most recent call last):\n  File \"/Users/susiegrigson/opt/anaconda3/envs/phynteny/lib/python3.8/site-packages/sklearn/model_selection/_validation.py\", line 686, in _fit_and_score\n    estimator.fit(X_train, y_train, **fit_params)\n  File \"/Users/susiegrigson/opt/anaconda3/envs/phynteny/lib/python3.8/site-packages/scikeras/wrappers.py\", line 1494, in fit\n    super().fit(X=X, y=y, sample_weight=sample_weight, **kwargs)\n  File \"/Users/susiegrigson/opt/anaconda3/envs/phynteny/lib/python3.8/site-packages/scikeras/wrappers.py\", line 762, in fit\n    self._fit(\n  File \"/Users/susiegrigson/opt/anaconda3/envs/phynteny/lib/python3.8/site-packages/scikeras/wrappers.py\", line 931, in _fit\n    self._fit_keras_model(\n  File \"/Users/susiegrigson/opt/anaconda3/envs/phynteny/lib/python3.8/site-packages/scikeras/wrappers.py\", line 526, in _fit_keras_model\n    hist = self.model_.fit(x=X, y=y, **fit_args)\n  File \"/Users/susiegrigson/opt/anaconda3/envs/phynteny/lib/python3.8/site-packages/keras/utils/traceback_utils.py\", line 70, in error_handler\n    raise e.with_traceback(filtered_tb) from None\n  File \"/var/folders/df/d2hn3bdx7dj7syrpbrxgtzkw0000gn/T/__autograph_generated_filean4lp6ve.py\", line 15, in tf__train_function\n    retval_ = ag__.converted_call(ag__.ld(step_function), (ag__.ld(self), ag__.ld(iterator)), None, fscope)\nValueError: in user code:\n\n    File \"/Users/susiegrigson/opt/anaconda3/envs/phynteny/lib/python3.8/site-packages/keras/engine/training.py\", line 1160, in train_function  *\n        return step_function(self, iterator)\n    File \"/Users/susiegrigson/opt/anaconda3/envs/phynteny/lib/python3.8/site-packages/keras/engine/training.py\", line 1146, in step_function  **\n        outputs = model.distribute_strategy.run(run_step, args=(data,))\n    File \"/Users/susiegrigson/opt/anaconda3/envs/phynteny/lib/python3.8/site-packages/keras/engine/training.py\", line 1135, in run_step  **\n        outputs = model.train_step(data)\n    File \"/Users/susiegrigson/opt/anaconda3/envs/phynteny/lib/python3.8/site-packages/keras/engine/training.py\", line 993, in train_step\n        y_pred = self(x, training=True)\n    File \"/Users/susiegrigson/opt/anaconda3/envs/phynteny/lib/python3.8/site-packages/keras/utils/traceback_utils.py\", line 70, in error_handler\n        raise e.with_traceback(filtered_tb) from None\n    File \"/Users/susiegrigson/opt/anaconda3/envs/phynteny/lib/python3.8/site-packages/keras/engine/input_spec.py\", line 295, in assert_input_compatibility\n        raise ValueError(\n\n    ValueError: Input 0 of layer \"sequential_8\" is incompatible with the layer: expected shape=(None, 1, 1920), found shape=(None, 1920)\n\n\n--------------------------------------------------------------------------------\n1 fits failed with the following error:\nTraceback (most recent call last):\n  File \"/Users/susiegrigson/opt/anaconda3/envs/phynteny/lib/python3.8/site-packages/sklearn/model_selection/_validation.py\", line 686, in _fit_and_score\n    estimator.fit(X_train, y_train, **fit_params)\n  File \"/Users/susiegrigson/opt/anaconda3/envs/phynteny/lib/python3.8/site-packages/scikeras/wrappers.py\", line 1494, in fit\n    super().fit(X=X, y=y, sample_weight=sample_weight, **kwargs)\n  File \"/Users/susiegrigson/opt/anaconda3/envs/phynteny/lib/python3.8/site-packages/scikeras/wrappers.py\", line 762, in fit\n    self._fit(\n  File \"/Users/susiegrigson/opt/anaconda3/envs/phynteny/lib/python3.8/site-packages/scikeras/wrappers.py\", line 931, in _fit\n    self._fit_keras_model(\n  File \"/Users/susiegrigson/opt/anaconda3/envs/phynteny/lib/python3.8/site-packages/scikeras/wrappers.py\", line 526, in _fit_keras_model\n    hist = self.model_.fit(x=X, y=y, **fit_args)\n  File \"/Users/susiegrigson/opt/anaconda3/envs/phynteny/lib/python3.8/site-packages/keras/utils/traceback_utils.py\", line 70, in error_handler\n    raise e.with_traceback(filtered_tb) from None\n  File \"/var/folders/df/d2hn3bdx7dj7syrpbrxgtzkw0000gn/T/__autograph_generated_filebkve13vq.py\", line 15, in tf__train_function\n    retval_ = ag__.converted_call(ag__.ld(step_function), (ag__.ld(self), ag__.ld(iterator)), None, fscope)\nValueError: in user code:\n\n    File \"/Users/susiegrigson/opt/anaconda3/envs/phynteny/lib/python3.8/site-packages/keras/engine/training.py\", line 1160, in train_function  *\n        return step_function(self, iterator)\n    File \"/Users/susiegrigson/opt/anaconda3/envs/phynteny/lib/python3.8/site-packages/keras/engine/training.py\", line 1146, in step_function  **\n        outputs = model.distribute_strategy.run(run_step, args=(data,))\n    File \"/Users/susiegrigson/opt/anaconda3/envs/phynteny/lib/python3.8/site-packages/keras/engine/training.py\", line 1135, in run_step  **\n        outputs = model.train_step(data)\n    File \"/Users/susiegrigson/opt/anaconda3/envs/phynteny/lib/python3.8/site-packages/keras/engine/training.py\", line 993, in train_step\n        y_pred = self(x, training=True)\n    File \"/Users/susiegrigson/opt/anaconda3/envs/phynteny/lib/python3.8/site-packages/keras/utils/traceback_utils.py\", line 70, in error_handler\n        raise e.with_traceback(filtered_tb) from None\n    File \"/Users/susiegrigson/opt/anaconda3/envs/phynteny/lib/python3.8/site-packages/keras/engine/input_spec.py\", line 295, in assert_input_compatibility\n        raise ValueError(\n\n    ValueError: Input 0 of layer \"sequential_10\" is incompatible with the layer: expected shape=(None, 1, 1920), found shape=(None, 1920)\n\n\n--------------------------------------------------------------------------------\n1 fits failed with the following error:\nTraceback (most recent call last):\n  File \"/Users/susiegrigson/opt/anaconda3/envs/phynteny/lib/python3.8/site-packages/sklearn/model_selection/_validation.py\", line 686, in _fit_and_score\n    estimator.fit(X_train, y_train, **fit_params)\n  File \"/Users/susiegrigson/opt/anaconda3/envs/phynteny/lib/python3.8/site-packages/scikeras/wrappers.py\", line 1494, in fit\n    super().fit(X=X, y=y, sample_weight=sample_weight, **kwargs)\n  File \"/Users/susiegrigson/opt/anaconda3/envs/phynteny/lib/python3.8/site-packages/scikeras/wrappers.py\", line 762, in fit\n    self._fit(\n  File \"/Users/susiegrigson/opt/anaconda3/envs/phynteny/lib/python3.8/site-packages/scikeras/wrappers.py\", line 931, in _fit\n    self._fit_keras_model(\n  File \"/Users/susiegrigson/opt/anaconda3/envs/phynteny/lib/python3.8/site-packages/scikeras/wrappers.py\", line 526, in _fit_keras_model\n    hist = self.model_.fit(x=X, y=y, **fit_args)\n  File \"/Users/susiegrigson/opt/anaconda3/envs/phynteny/lib/python3.8/site-packages/keras/utils/traceback_utils.py\", line 70, in error_handler\n    raise e.with_traceback(filtered_tb) from None\n  File \"/var/folders/df/d2hn3bdx7dj7syrpbrxgtzkw0000gn/T/__autograph_generated_fileuin_5wmx.py\", line 15, in tf__train_function\n    retval_ = ag__.converted_call(ag__.ld(step_function), (ag__.ld(self), ag__.ld(iterator)), None, fscope)\nValueError: in user code:\n\n    File \"/Users/susiegrigson/opt/anaconda3/envs/phynteny/lib/python3.8/site-packages/keras/engine/training.py\", line 1160, in train_function  *\n        return step_function(self, iterator)\n    File \"/Users/susiegrigson/opt/anaconda3/envs/phynteny/lib/python3.8/site-packages/keras/engine/training.py\", line 1146, in step_function  **\n        outputs = model.distribute_strategy.run(run_step, args=(data,))\n    File \"/Users/susiegrigson/opt/anaconda3/envs/phynteny/lib/python3.8/site-packages/keras/engine/training.py\", line 1135, in run_step  **\n        outputs = model.train_step(data)\n    File \"/Users/susiegrigson/opt/anaconda3/envs/phynteny/lib/python3.8/site-packages/keras/engine/training.py\", line 993, in train_step\n        y_pred = self(x, training=True)\n    File \"/Users/susiegrigson/opt/anaconda3/envs/phynteny/lib/python3.8/site-packages/keras/utils/traceback_utils.py\", line 70, in error_handler\n        raise e.with_traceback(filtered_tb) from None\n    File \"/Users/susiegrigson/opt/anaconda3/envs/phynteny/lib/python3.8/site-packages/keras/engine/input_spec.py\", line 295, in assert_input_compatibility\n        raise ValueError(\n\n    ValueError: Input 0 of layer \"sequential_8\" is incompatible with the layer: expected shape=(None, 1, 1920), found shape=(None, 1920)\n\n\n--------------------------------------------------------------------------------\n1 fits failed with the following error:\nTraceback (most recent call last):\n  File \"/Users/susiegrigson/opt/anaconda3/envs/phynteny/lib/python3.8/site-packages/sklearn/model_selection/_validation.py\", line 686, in _fit_and_score\n    estimator.fit(X_train, y_train, **fit_params)\n  File \"/Users/susiegrigson/opt/anaconda3/envs/phynteny/lib/python3.8/site-packages/scikeras/wrappers.py\", line 1494, in fit\n    super().fit(X=X, y=y, sample_weight=sample_weight, **kwargs)\n  File \"/Users/susiegrigson/opt/anaconda3/envs/phynteny/lib/python3.8/site-packages/scikeras/wrappers.py\", line 762, in fit\n    self._fit(\n  File \"/Users/susiegrigson/opt/anaconda3/envs/phynteny/lib/python3.8/site-packages/scikeras/wrappers.py\", line 931, in _fit\n    self._fit_keras_model(\n  File \"/Users/susiegrigson/opt/anaconda3/envs/phynteny/lib/python3.8/site-packages/scikeras/wrappers.py\", line 526, in _fit_keras_model\n    hist = self.model_.fit(x=X, y=y, **fit_args)\n  File \"/Users/susiegrigson/opt/anaconda3/envs/phynteny/lib/python3.8/site-packages/keras/utils/traceback_utils.py\", line 70, in error_handler\n    raise e.with_traceback(filtered_tb) from None\n  File \"/var/folders/df/d2hn3bdx7dj7syrpbrxgtzkw0000gn/T/__autograph_generated_filenvqcw9qf.py\", line 15, in tf__train_function\n    retval_ = ag__.converted_call(ag__.ld(step_function), (ag__.ld(self), ag__.ld(iterator)), None, fscope)\nValueError: in user code:\n\n    File \"/Users/susiegrigson/opt/anaconda3/envs/phynteny/lib/python3.8/site-packages/keras/engine/training.py\", line 1160, in train_function  *\n        return step_function(self, iterator)\n    File \"/Users/susiegrigson/opt/anaconda3/envs/phynteny/lib/python3.8/site-packages/keras/engine/training.py\", line 1146, in step_function  **\n        outputs = model.distribute_strategy.run(run_step, args=(data,))\n    File \"/Users/susiegrigson/opt/anaconda3/envs/phynteny/lib/python3.8/site-packages/keras/engine/training.py\", line 1135, in run_step  **\n        outputs = model.train_step(data)\n    File \"/Users/susiegrigson/opt/anaconda3/envs/phynteny/lib/python3.8/site-packages/keras/engine/training.py\", line 993, in train_step\n        y_pred = self(x, training=True)\n    File \"/Users/susiegrigson/opt/anaconda3/envs/phynteny/lib/python3.8/site-packages/keras/utils/traceback_utils.py\", line 70, in error_handler\n        raise e.with_traceback(filtered_tb) from None\n    File \"/Users/susiegrigson/opt/anaconda3/envs/phynteny/lib/python3.8/site-packages/keras/engine/input_spec.py\", line 295, in assert_input_compatibility\n        raise ValueError(\n\n    ValueError: Input 0 of layer \"sequential_9\" is incompatible with the layer: expected shape=(None, 1, 1920), found shape=(None, 1920)\n\n\n--------------------------------------------------------------------------------\n1 fits failed with the following error:\nTraceback (most recent call last):\n  File \"/Users/susiegrigson/opt/anaconda3/envs/phynteny/lib/python3.8/site-packages/sklearn/model_selection/_validation.py\", line 686, in _fit_and_score\n    estimator.fit(X_train, y_train, **fit_params)\n  File \"/Users/susiegrigson/opt/anaconda3/envs/phynteny/lib/python3.8/site-packages/scikeras/wrappers.py\", line 1494, in fit\n    super().fit(X=X, y=y, sample_weight=sample_weight, **kwargs)\n  File \"/Users/susiegrigson/opt/anaconda3/envs/phynteny/lib/python3.8/site-packages/scikeras/wrappers.py\", line 762, in fit\n    self._fit(\n  File \"/Users/susiegrigson/opt/anaconda3/envs/phynteny/lib/python3.8/site-packages/scikeras/wrappers.py\", line 931, in _fit\n    self._fit_keras_model(\n  File \"/Users/susiegrigson/opt/anaconda3/envs/phynteny/lib/python3.8/site-packages/scikeras/wrappers.py\", line 526, in _fit_keras_model\n    hist = self.model_.fit(x=X, y=y, **fit_args)\n  File \"/Users/susiegrigson/opt/anaconda3/envs/phynteny/lib/python3.8/site-packages/keras/utils/traceback_utils.py\", line 70, in error_handler\n    raise e.with_traceback(filtered_tb) from None\n  File \"/var/folders/df/d2hn3bdx7dj7syrpbrxgtzkw0000gn/T/__autograph_generated_filext2s2_c4.py\", line 15, in tf__train_function\n    retval_ = ag__.converted_call(ag__.ld(step_function), (ag__.ld(self), ag__.ld(iterator)), None, fscope)\nValueError: in user code:\n\n    File \"/Users/susiegrigson/opt/anaconda3/envs/phynteny/lib/python3.8/site-packages/keras/engine/training.py\", line 1160, in train_function  *\n        return step_function(self, iterator)\n    File \"/Users/susiegrigson/opt/anaconda3/envs/phynteny/lib/python3.8/site-packages/keras/engine/training.py\", line 1146, in step_function  **\n        outputs = model.distribute_strategy.run(run_step, args=(data,))\n    File \"/Users/susiegrigson/opt/anaconda3/envs/phynteny/lib/python3.8/site-packages/keras/engine/training.py\", line 1135, in run_step  **\n        outputs = model.train_step(data)\n    File \"/Users/susiegrigson/opt/anaconda3/envs/phynteny/lib/python3.8/site-packages/keras/engine/training.py\", line 993, in train_step\n        y_pred = self(x, training=True)\n    File \"/Users/susiegrigson/opt/anaconda3/envs/phynteny/lib/python3.8/site-packages/keras/utils/traceback_utils.py\", line 70, in error_handler\n        raise e.with_traceback(filtered_tb) from None\n    File \"/Users/susiegrigson/opt/anaconda3/envs/phynteny/lib/python3.8/site-packages/keras/engine/input_spec.py\", line 295, in assert_input_compatibility\n        raise ValueError(\n\n    ValueError: Input 0 of layer \"sequential_10\" is incompatible with the layer: expected shape=(None, 1, 1920), found shape=(None, 1920)\n\n\n--------------------------------------------------------------------------------\n1 fits failed with the following error:\nTraceback (most recent call last):\n  File \"/Users/susiegrigson/opt/anaconda3/envs/phynteny/lib/python3.8/site-packages/sklearn/model_selection/_validation.py\", line 686, in _fit_and_score\n    estimator.fit(X_train, y_train, **fit_params)\n  File \"/Users/susiegrigson/opt/anaconda3/envs/phynteny/lib/python3.8/site-packages/scikeras/wrappers.py\", line 1494, in fit\n    super().fit(X=X, y=y, sample_weight=sample_weight, **kwargs)\n  File \"/Users/susiegrigson/opt/anaconda3/envs/phynteny/lib/python3.8/site-packages/scikeras/wrappers.py\", line 762, in fit\n    self._fit(\n  File \"/Users/susiegrigson/opt/anaconda3/envs/phynteny/lib/python3.8/site-packages/scikeras/wrappers.py\", line 931, in _fit\n    self._fit_keras_model(\n  File \"/Users/susiegrigson/opt/anaconda3/envs/phynteny/lib/python3.8/site-packages/scikeras/wrappers.py\", line 526, in _fit_keras_model\n    hist = self.model_.fit(x=X, y=y, **fit_args)\n  File \"/Users/susiegrigson/opt/anaconda3/envs/phynteny/lib/python3.8/site-packages/keras/utils/traceback_utils.py\", line 70, in error_handler\n    raise e.with_traceback(filtered_tb) from None\n  File \"/var/folders/df/d2hn3bdx7dj7syrpbrxgtzkw0000gn/T/__autograph_generated_filemelktkna.py\", line 15, in tf__train_function\n    retval_ = ag__.converted_call(ag__.ld(step_function), (ag__.ld(self), ag__.ld(iterator)), None, fscope)\nValueError: in user code:\n\n    File \"/Users/susiegrigson/opt/anaconda3/envs/phynteny/lib/python3.8/site-packages/keras/engine/training.py\", line 1160, in train_function  *\n        return step_function(self, iterator)\n    File \"/Users/susiegrigson/opt/anaconda3/envs/phynteny/lib/python3.8/site-packages/keras/engine/training.py\", line 1146, in step_function  **\n        outputs = model.distribute_strategy.run(run_step, args=(data,))\n    File \"/Users/susiegrigson/opt/anaconda3/envs/phynteny/lib/python3.8/site-packages/keras/engine/training.py\", line 1135, in run_step  **\n        outputs = model.train_step(data)\n    File \"/Users/susiegrigson/opt/anaconda3/envs/phynteny/lib/python3.8/site-packages/keras/engine/training.py\", line 993, in train_step\n        y_pred = self(x, training=True)\n    File \"/Users/susiegrigson/opt/anaconda3/envs/phynteny/lib/python3.8/site-packages/keras/utils/traceback_utils.py\", line 70, in error_handler\n        raise e.with_traceback(filtered_tb) from None\n    File \"/Users/susiegrigson/opt/anaconda3/envs/phynteny/lib/python3.8/site-packages/keras/engine/input_spec.py\", line 295, in assert_input_compatibility\n        raise ValueError(\n\n    ValueError: Input 0 of layer \"sequential_9\" is incompatible with the layer: expected shape=(None, 1, 1920), found shape=(None, 1920)\n\n\n--------------------------------------------------------------------------------\n1 fits failed with the following error:\nTraceback (most recent call last):\n  File \"/Users/susiegrigson/opt/anaconda3/envs/phynteny/lib/python3.8/site-packages/sklearn/model_selection/_validation.py\", line 686, in _fit_and_score\n    estimator.fit(X_train, y_train, **fit_params)\n  File \"/Users/susiegrigson/opt/anaconda3/envs/phynteny/lib/python3.8/site-packages/scikeras/wrappers.py\", line 1494, in fit\n    super().fit(X=X, y=y, sample_weight=sample_weight, **kwargs)\n  File \"/Users/susiegrigson/opt/anaconda3/envs/phynteny/lib/python3.8/site-packages/scikeras/wrappers.py\", line 762, in fit\n    self._fit(\n  File \"/Users/susiegrigson/opt/anaconda3/envs/phynteny/lib/python3.8/site-packages/scikeras/wrappers.py\", line 931, in _fit\n    self._fit_keras_model(\n  File \"/Users/susiegrigson/opt/anaconda3/envs/phynteny/lib/python3.8/site-packages/scikeras/wrappers.py\", line 526, in _fit_keras_model\n    hist = self.model_.fit(x=X, y=y, **fit_args)\n  File \"/Users/susiegrigson/opt/anaconda3/envs/phynteny/lib/python3.8/site-packages/keras/utils/traceback_utils.py\", line 70, in error_handler\n    raise e.with_traceback(filtered_tb) from None\n  File \"/var/folders/df/d2hn3bdx7dj7syrpbrxgtzkw0000gn/T/__autograph_generated_filepgzqv3j0.py\", line 15, in tf__train_function\n    retval_ = ag__.converted_call(ag__.ld(step_function), (ag__.ld(self), ag__.ld(iterator)), None, fscope)\nValueError: in user code:\n\n    File \"/Users/susiegrigson/opt/anaconda3/envs/phynteny/lib/python3.8/site-packages/keras/engine/training.py\", line 1160, in train_function  *\n        return step_function(self, iterator)\n    File \"/Users/susiegrigson/opt/anaconda3/envs/phynteny/lib/python3.8/site-packages/keras/engine/training.py\", line 1146, in step_function  **\n        outputs = model.distribute_strategy.run(run_step, args=(data,))\n    File \"/Users/susiegrigson/opt/anaconda3/envs/phynteny/lib/python3.8/site-packages/keras/engine/training.py\", line 1135, in run_step  **\n        outputs = model.train_step(data)\n    File \"/Users/susiegrigson/opt/anaconda3/envs/phynteny/lib/python3.8/site-packages/keras/engine/training.py\", line 993, in train_step\n        y_pred = self(x, training=True)\n    File \"/Users/susiegrigson/opt/anaconda3/envs/phynteny/lib/python3.8/site-packages/keras/utils/traceback_utils.py\", line 70, in error_handler\n        raise e.with_traceback(filtered_tb) from None\n    File \"/Users/susiegrigson/opt/anaconda3/envs/phynteny/lib/python3.8/site-packages/keras/engine/input_spec.py\", line 295, in assert_input_compatibility\n        raise ValueError(\n\n    ValueError: Input 0 of layer \"sequential_9\" is incompatible with the layer: expected shape=(None, 1, 1920), found shape=(None, 1920)\n\n\n--------------------------------------------------------------------------------\n1 fits failed with the following error:\nTraceback (most recent call last):\n  File \"/Users/susiegrigson/opt/anaconda3/envs/phynteny/lib/python3.8/site-packages/sklearn/model_selection/_validation.py\", line 686, in _fit_and_score\n    estimator.fit(X_train, y_train, **fit_params)\n  File \"/Users/susiegrigson/opt/anaconda3/envs/phynteny/lib/python3.8/site-packages/scikeras/wrappers.py\", line 1494, in fit\n    super().fit(X=X, y=y, sample_weight=sample_weight, **kwargs)\n  File \"/Users/susiegrigson/opt/anaconda3/envs/phynteny/lib/python3.8/site-packages/scikeras/wrappers.py\", line 762, in fit\n    self._fit(\n  File \"/Users/susiegrigson/opt/anaconda3/envs/phynteny/lib/python3.8/site-packages/scikeras/wrappers.py\", line 931, in _fit\n    self._fit_keras_model(\n  File \"/Users/susiegrigson/opt/anaconda3/envs/phynteny/lib/python3.8/site-packages/scikeras/wrappers.py\", line 526, in _fit_keras_model\n    hist = self.model_.fit(x=X, y=y, **fit_args)\n  File \"/Users/susiegrigson/opt/anaconda3/envs/phynteny/lib/python3.8/site-packages/keras/utils/traceback_utils.py\", line 70, in error_handler\n    raise e.with_traceback(filtered_tb) from None\n  File \"/var/folders/df/d2hn3bdx7dj7syrpbrxgtzkw0000gn/T/__autograph_generated_fileusdxkgvw.py\", line 15, in tf__train_function\n    retval_ = ag__.converted_call(ag__.ld(step_function), (ag__.ld(self), ag__.ld(iterator)), None, fscope)\nValueError: in user code:\n\n    File \"/Users/susiegrigson/opt/anaconda3/envs/phynteny/lib/python3.8/site-packages/keras/engine/training.py\", line 1160, in train_function  *\n        return step_function(self, iterator)\n    File \"/Users/susiegrigson/opt/anaconda3/envs/phynteny/lib/python3.8/site-packages/keras/engine/training.py\", line 1146, in step_function  **\n        outputs = model.distribute_strategy.run(run_step, args=(data,))\n    File \"/Users/susiegrigson/opt/anaconda3/envs/phynteny/lib/python3.8/site-packages/keras/engine/training.py\", line 1135, in run_step  **\n        outputs = model.train_step(data)\n    File \"/Users/susiegrigson/opt/anaconda3/envs/phynteny/lib/python3.8/site-packages/keras/engine/training.py\", line 993, in train_step\n        y_pred = self(x, training=True)\n    File \"/Users/susiegrigson/opt/anaconda3/envs/phynteny/lib/python3.8/site-packages/keras/utils/traceback_utils.py\", line 70, in error_handler\n        raise e.with_traceback(filtered_tb) from None\n    File \"/Users/susiegrigson/opt/anaconda3/envs/phynteny/lib/python3.8/site-packages/keras/engine/input_spec.py\", line 295, in assert_input_compatibility\n        raise ValueError(\n\n    ValueError: Input 0 of layer \"sequential_9\" is incompatible with the layer: expected shape=(None, 1, 1920), found shape=(None, 1920)\n\n\n--------------------------------------------------------------------------------\n1 fits failed with the following error:\nTraceback (most recent call last):\n  File \"/Users/susiegrigson/opt/anaconda3/envs/phynteny/lib/python3.8/site-packages/sklearn/model_selection/_validation.py\", line 686, in _fit_and_score\n    estimator.fit(X_train, y_train, **fit_params)\n  File \"/Users/susiegrigson/opt/anaconda3/envs/phynteny/lib/python3.8/site-packages/scikeras/wrappers.py\", line 1494, in fit\n    super().fit(X=X, y=y, sample_weight=sample_weight, **kwargs)\n  File \"/Users/susiegrigson/opt/anaconda3/envs/phynteny/lib/python3.8/site-packages/scikeras/wrappers.py\", line 762, in fit\n    self._fit(\n  File \"/Users/susiegrigson/opt/anaconda3/envs/phynteny/lib/python3.8/site-packages/scikeras/wrappers.py\", line 931, in _fit\n    self._fit_keras_model(\n  File \"/Users/susiegrigson/opt/anaconda3/envs/phynteny/lib/python3.8/site-packages/scikeras/wrappers.py\", line 526, in _fit_keras_model\n    hist = self.model_.fit(x=X, y=y, **fit_args)\n  File \"/Users/susiegrigson/opt/anaconda3/envs/phynteny/lib/python3.8/site-packages/keras/utils/traceback_utils.py\", line 70, in error_handler\n    raise e.with_traceback(filtered_tb) from None\n  File \"/var/folders/df/d2hn3bdx7dj7syrpbrxgtzkw0000gn/T/__autograph_generated_filej5ika9tg.py\", line 15, in tf__train_function\n    retval_ = ag__.converted_call(ag__.ld(step_function), (ag__.ld(self), ag__.ld(iterator)), None, fscope)\nValueError: in user code:\n\n    File \"/Users/susiegrigson/opt/anaconda3/envs/phynteny/lib/python3.8/site-packages/keras/engine/training.py\", line 1160, in train_function  *\n        return step_function(self, iterator)\n    File \"/Users/susiegrigson/opt/anaconda3/envs/phynteny/lib/python3.8/site-packages/keras/engine/training.py\", line 1146, in step_function  **\n        outputs = model.distribute_strategy.run(run_step, args=(data,))\n    File \"/Users/susiegrigson/opt/anaconda3/envs/phynteny/lib/python3.8/site-packages/keras/engine/training.py\", line 1135, in run_step  **\n        outputs = model.train_step(data)\n    File \"/Users/susiegrigson/opt/anaconda3/envs/phynteny/lib/python3.8/site-packages/keras/engine/training.py\", line 993, in train_step\n        y_pred = self(x, training=True)\n    File \"/Users/susiegrigson/opt/anaconda3/envs/phynteny/lib/python3.8/site-packages/keras/utils/traceback_utils.py\", line 70, in error_handler\n        raise e.with_traceback(filtered_tb) from None\n    File \"/Users/susiegrigson/opt/anaconda3/envs/phynteny/lib/python3.8/site-packages/keras/engine/input_spec.py\", line 295, in assert_input_compatibility\n        raise ValueError(\n\n    ValueError: Input 0 of layer \"sequential_10\" is incompatible with the layer: expected shape=(None, 1, 1920), found shape=(None, 1920)\n\n\n--------------------------------------------------------------------------------\n1 fits failed with the following error:\nTraceback (most recent call last):\n  File \"/Users/susiegrigson/opt/anaconda3/envs/phynteny/lib/python3.8/site-packages/sklearn/model_selection/_validation.py\", line 686, in _fit_and_score\n    estimator.fit(X_train, y_train, **fit_params)\n  File \"/Users/susiegrigson/opt/anaconda3/envs/phynteny/lib/python3.8/site-packages/scikeras/wrappers.py\", line 1494, in fit\n    super().fit(X=X, y=y, sample_weight=sample_weight, **kwargs)\n  File \"/Users/susiegrigson/opt/anaconda3/envs/phynteny/lib/python3.8/site-packages/scikeras/wrappers.py\", line 762, in fit\n    self._fit(\n  File \"/Users/susiegrigson/opt/anaconda3/envs/phynteny/lib/python3.8/site-packages/scikeras/wrappers.py\", line 931, in _fit\n    self._fit_keras_model(\n  File \"/Users/susiegrigson/opt/anaconda3/envs/phynteny/lib/python3.8/site-packages/scikeras/wrappers.py\", line 526, in _fit_keras_model\n    hist = self.model_.fit(x=X, y=y, **fit_args)\n  File \"/Users/susiegrigson/opt/anaconda3/envs/phynteny/lib/python3.8/site-packages/keras/utils/traceback_utils.py\", line 70, in error_handler\n    raise e.with_traceback(filtered_tb) from None\n  File \"/var/folders/df/d2hn3bdx7dj7syrpbrxgtzkw0000gn/T/__autograph_generated_fileuin_5wmx.py\", line 15, in tf__train_function\n    retval_ = ag__.converted_call(ag__.ld(step_function), (ag__.ld(self), ag__.ld(iterator)), None, fscope)\nValueError: in user code:\n\n    File \"/Users/susiegrigson/opt/anaconda3/envs/phynteny/lib/python3.8/site-packages/keras/engine/training.py\", line 1160, in train_function  *\n        return step_function(self, iterator)\n    File \"/Users/susiegrigson/opt/anaconda3/envs/phynteny/lib/python3.8/site-packages/keras/engine/training.py\", line 1146, in step_function  **\n        outputs = model.distribute_strategy.run(run_step, args=(data,))\n    File \"/Users/susiegrigson/opt/anaconda3/envs/phynteny/lib/python3.8/site-packages/keras/engine/training.py\", line 1135, in run_step  **\n        outputs = model.train_step(data)\n    File \"/Users/susiegrigson/opt/anaconda3/envs/phynteny/lib/python3.8/site-packages/keras/engine/training.py\", line 993, in train_step\n        y_pred = self(x, training=True)\n    File \"/Users/susiegrigson/opt/anaconda3/envs/phynteny/lib/python3.8/site-packages/keras/utils/traceback_utils.py\", line 70, in error_handler\n        raise e.with_traceback(filtered_tb) from None\n    File \"/Users/susiegrigson/opt/anaconda3/envs/phynteny/lib/python3.8/site-packages/keras/engine/input_spec.py\", line 295, in assert_input_compatibility\n        raise ValueError(\n\n    ValueError: Input 0 of layer \"sequential_9\" is incompatible with the layer: expected shape=(None, 1, 1920), found shape=(None, 1920)\n\n\n--------------------------------------------------------------------------------\n1 fits failed with the following error:\nTraceback (most recent call last):\n  File \"/Users/susiegrigson/opt/anaconda3/envs/phynteny/lib/python3.8/site-packages/sklearn/model_selection/_validation.py\", line 686, in _fit_and_score\n    estimator.fit(X_train, y_train, **fit_params)\n  File \"/Users/susiegrigson/opt/anaconda3/envs/phynteny/lib/python3.8/site-packages/scikeras/wrappers.py\", line 1494, in fit\n    super().fit(X=X, y=y, sample_weight=sample_weight, **kwargs)\n  File \"/Users/susiegrigson/opt/anaconda3/envs/phynteny/lib/python3.8/site-packages/scikeras/wrappers.py\", line 762, in fit\n    self._fit(\n  File \"/Users/susiegrigson/opt/anaconda3/envs/phynteny/lib/python3.8/site-packages/scikeras/wrappers.py\", line 931, in _fit\n    self._fit_keras_model(\n  File \"/Users/susiegrigson/opt/anaconda3/envs/phynteny/lib/python3.8/site-packages/scikeras/wrappers.py\", line 526, in _fit_keras_model\n    hist = self.model_.fit(x=X, y=y, **fit_args)\n  File \"/Users/susiegrigson/opt/anaconda3/envs/phynteny/lib/python3.8/site-packages/keras/utils/traceback_utils.py\", line 70, in error_handler\n    raise e.with_traceback(filtered_tb) from None\n  File \"/var/folders/df/d2hn3bdx7dj7syrpbrxgtzkw0000gn/T/__autograph_generated_fileql9ao1yw.py\", line 15, in tf__train_function\n    retval_ = ag__.converted_call(ag__.ld(step_function), (ag__.ld(self), ag__.ld(iterator)), None, fscope)\nValueError: in user code:\n\n    File \"/Users/susiegrigson/opt/anaconda3/envs/phynteny/lib/python3.8/site-packages/keras/engine/training.py\", line 1160, in train_function  *\n        return step_function(self, iterator)\n    File \"/Users/susiegrigson/opt/anaconda3/envs/phynteny/lib/python3.8/site-packages/keras/engine/training.py\", line 1146, in step_function  **\n        outputs = model.distribute_strategy.run(run_step, args=(data,))\n    File \"/Users/susiegrigson/opt/anaconda3/envs/phynteny/lib/python3.8/site-packages/keras/engine/training.py\", line 1135, in run_step  **\n        outputs = model.train_step(data)\n    File \"/Users/susiegrigson/opt/anaconda3/envs/phynteny/lib/python3.8/site-packages/keras/engine/training.py\", line 993, in train_step\n        y_pred = self(x, training=True)\n    File \"/Users/susiegrigson/opt/anaconda3/envs/phynteny/lib/python3.8/site-packages/keras/utils/traceback_utils.py\", line 70, in error_handler\n        raise e.with_traceback(filtered_tb) from None\n    File \"/Users/susiegrigson/opt/anaconda3/envs/phynteny/lib/python3.8/site-packages/keras/engine/input_spec.py\", line 295, in assert_input_compatibility\n        raise ValueError(\n\n    ValueError: Input 0 of layer \"sequential_10\" is incompatible with the layer: expected shape=(None, 1, 1920), found shape=(None, 1920)\n\n\n--------------------------------------------------------------------------------\n1 fits failed with the following error:\nTraceback (most recent call last):\n  File \"/Users/susiegrigson/opt/anaconda3/envs/phynteny/lib/python3.8/site-packages/sklearn/model_selection/_validation.py\", line 686, in _fit_and_score\n    estimator.fit(X_train, y_train, **fit_params)\n  File \"/Users/susiegrigson/opt/anaconda3/envs/phynteny/lib/python3.8/site-packages/scikeras/wrappers.py\", line 1494, in fit\n    super().fit(X=X, y=y, sample_weight=sample_weight, **kwargs)\n  File \"/Users/susiegrigson/opt/anaconda3/envs/phynteny/lib/python3.8/site-packages/scikeras/wrappers.py\", line 762, in fit\n    self._fit(\n  File \"/Users/susiegrigson/opt/anaconda3/envs/phynteny/lib/python3.8/site-packages/scikeras/wrappers.py\", line 931, in _fit\n    self._fit_keras_model(\n  File \"/Users/susiegrigson/opt/anaconda3/envs/phynteny/lib/python3.8/site-packages/scikeras/wrappers.py\", line 526, in _fit_keras_model\n    hist = self.model_.fit(x=X, y=y, **fit_args)\n  File \"/Users/susiegrigson/opt/anaconda3/envs/phynteny/lib/python3.8/site-packages/keras/utils/traceback_utils.py\", line 70, in error_handler\n    raise e.with_traceback(filtered_tb) from None\n  File \"/var/folders/df/d2hn3bdx7dj7syrpbrxgtzkw0000gn/T/__autograph_generated_filext2s2_c4.py\", line 15, in tf__train_function\n    retval_ = ag__.converted_call(ag__.ld(step_function), (ag__.ld(self), ag__.ld(iterator)), None, fscope)\nValueError: in user code:\n\n    File \"/Users/susiegrigson/opt/anaconda3/envs/phynteny/lib/python3.8/site-packages/keras/engine/training.py\", line 1160, in train_function  *\n        return step_function(self, iterator)\n    File \"/Users/susiegrigson/opt/anaconda3/envs/phynteny/lib/python3.8/site-packages/keras/engine/training.py\", line 1146, in step_function  **\n        outputs = model.distribute_strategy.run(run_step, args=(data,))\n    File \"/Users/susiegrigson/opt/anaconda3/envs/phynteny/lib/python3.8/site-packages/keras/engine/training.py\", line 1135, in run_step  **\n        outputs = model.train_step(data)\n    File \"/Users/susiegrigson/opt/anaconda3/envs/phynteny/lib/python3.8/site-packages/keras/engine/training.py\", line 993, in train_step\n        y_pred = self(x, training=True)\n    File \"/Users/susiegrigson/opt/anaconda3/envs/phynteny/lib/python3.8/site-packages/keras/utils/traceback_utils.py\", line 70, in error_handler\n        raise e.with_traceback(filtered_tb) from None\n    File \"/Users/susiegrigson/opt/anaconda3/envs/phynteny/lib/python3.8/site-packages/keras/engine/input_spec.py\", line 295, in assert_input_compatibility\n        raise ValueError(\n\n    ValueError: Input 0 of layer \"sequential_11\" is incompatible with the layer: expected shape=(None, 1, 1920), found shape=(None, 1920)\n\n\n--------------------------------------------------------------------------------\n1 fits failed with the following error:\nTraceback (most recent call last):\n  File \"/Users/susiegrigson/opt/anaconda3/envs/phynteny/lib/python3.8/site-packages/sklearn/model_selection/_validation.py\", line 686, in _fit_and_score\n    estimator.fit(X_train, y_train, **fit_params)\n  File \"/Users/susiegrigson/opt/anaconda3/envs/phynteny/lib/python3.8/site-packages/scikeras/wrappers.py\", line 1494, in fit\n    super().fit(X=X, y=y, sample_weight=sample_weight, **kwargs)\n  File \"/Users/susiegrigson/opt/anaconda3/envs/phynteny/lib/python3.8/site-packages/scikeras/wrappers.py\", line 762, in fit\n    self._fit(\n  File \"/Users/susiegrigson/opt/anaconda3/envs/phynteny/lib/python3.8/site-packages/scikeras/wrappers.py\", line 931, in _fit\n    self._fit_keras_model(\n  File \"/Users/susiegrigson/opt/anaconda3/envs/phynteny/lib/python3.8/site-packages/scikeras/wrappers.py\", line 526, in _fit_keras_model\n    hist = self.model_.fit(x=X, y=y, **fit_args)\n  File \"/Users/susiegrigson/opt/anaconda3/envs/phynteny/lib/python3.8/site-packages/keras/utils/traceback_utils.py\", line 70, in error_handler\n    raise e.with_traceback(filtered_tb) from None\n  File \"/var/folders/df/d2hn3bdx7dj7syrpbrxgtzkw0000gn/T/__autograph_generated_filepgzqv3j0.py\", line 15, in tf__train_function\n    retval_ = ag__.converted_call(ag__.ld(step_function), (ag__.ld(self), ag__.ld(iterator)), None, fscope)\nValueError: in user code:\n\n    File \"/Users/susiegrigson/opt/anaconda3/envs/phynteny/lib/python3.8/site-packages/keras/engine/training.py\", line 1160, in train_function  *\n        return step_function(self, iterator)\n    File \"/Users/susiegrigson/opt/anaconda3/envs/phynteny/lib/python3.8/site-packages/keras/engine/training.py\", line 1146, in step_function  **\n        outputs = model.distribute_strategy.run(run_step, args=(data,))\n    File \"/Users/susiegrigson/opt/anaconda3/envs/phynteny/lib/python3.8/site-packages/keras/engine/training.py\", line 1135, in run_step  **\n        outputs = model.train_step(data)\n    File \"/Users/susiegrigson/opt/anaconda3/envs/phynteny/lib/python3.8/site-packages/keras/engine/training.py\", line 993, in train_step\n        y_pred = self(x, training=True)\n    File \"/Users/susiegrigson/opt/anaconda3/envs/phynteny/lib/python3.8/site-packages/keras/utils/traceback_utils.py\", line 70, in error_handler\n        raise e.with_traceback(filtered_tb) from None\n    File \"/Users/susiegrigson/opt/anaconda3/envs/phynteny/lib/python3.8/site-packages/keras/engine/input_spec.py\", line 295, in assert_input_compatibility\n        raise ValueError(\n\n    ValueError: Input 0 of layer \"sequential_10\" is incompatible with the layer: expected shape=(None, 1, 1920), found shape=(None, 1920)\n\n"
     ]
    }
   ],
   "source": [
    "train_model.perform_search(X,y)"
   ],
   "metadata": {
    "collapsed": false
   }
  },
  {
   "cell_type": "code",
   "execution_count": 66,
   "outputs": [
    {
     "name": "stdout",
     "output_type": "stream",
     "text": [
      "KerasClassifier(\n",
      "\tmodel=<function generate_LSTM at 0x7fa6e801cdc0>\n",
      "\tbuild_fn=None\n",
      "\twarm_start=False\n",
      "\trandom_state=None\n",
      "\toptimizer=rmsprop\n",
      "\tloss=None\n",
      "\tmetrics=None\n",
      "\tbatch_size=None\n",
      "\tvalidation_batch_size=None\n",
      "\tverbose=0\n",
      "\tcallbacks=None\n",
      "\tvalidation_split=0.0\n",
      "\tshuffle=True\n",
      "\trun_eagerly=False\n",
      "\tepochs=1\n",
      "\tclass_weight=None\n",
      ")\n",
      "(10, 1920)\n",
      "(10, 1200)\n"
     ]
    },
    {
     "ename": "BrokenProcessPool",
     "evalue": "A task has failed to un-serialize. Please ensure that the arguments of the function are all picklable.",
     "output_type": "error",
     "traceback": [
      "\u001B[0;31m---------------------------------------------------------------------------\u001B[0m",
      "\u001B[0;31m_RemoteTraceback\u001B[0m                          Traceback (most recent call last)",
      "\u001B[0;31m_RemoteTraceback\u001B[0m: \n\"\"\"\nTraceback (most recent call last):\n  File \"/Users/susiegrigson/opt/anaconda3/envs/phynteny/lib/python3.8/site-packages/joblib/externals/loky/process_executor.py\", line 391, in _process_worker\n    call_item = call_queue.get(block=True, timeout=timeout)\n  File \"/Users/susiegrigson/opt/anaconda3/envs/phynteny/lib/python3.8/multiprocessing/queues.py\", line 116, in get\n    return _ForkingPickler.loads(res)\nAttributeError: Can't get attribute 'generate_LSTM' on <module 'phynteny_utils.train_model' from '/Users/susiegrigson/PycharmProjects/Phynteny/phynteny_utils/train_model.py'>\n\"\"\"",
      "\nThe above exception was the direct cause of the following exception:\n",
      "\u001B[0;31mBrokenProcessPool\u001B[0m                         Traceback (most recent call last)",
      "\u001B[0;32m<ipython-input-66-854c99801843>\u001B[0m in \u001B[0;36m<module>\u001B[0;34m\u001B[0m\n\u001B[1;32m      3\u001B[0m \u001B[0mmodel\u001B[0m\u001B[0;34m.\u001B[0m\u001B[0mparse_data\u001B[0m\u001B[0;34m(\u001B[0m\u001B[0msubset_dict\u001B[0m\u001B[0;34m)\u001B[0m\u001B[0;34m\u001B[0m\u001B[0;34m\u001B[0m\u001B[0m\n\u001B[1;32m      4\u001B[0m \u001B[0;31m#created = model.generate_LSTM(layers = 0) #create a phynteny model which has one layer\u001B[0m\u001B[0;34m\u001B[0m\u001B[0;34m\u001B[0m\u001B[0;34m\u001B[0m\u001B[0m\n\u001B[0;32m----> 5\u001B[0;31m \u001B[0mmodel\u001B[0m\u001B[0;34m.\u001B[0m\u001B[0mperform_search\u001B[0m\u001B[0;34m(\u001B[0m\u001B[0;34m)\u001B[0m\u001B[0;34m\u001B[0m\u001B[0;34m\u001B[0m\u001B[0m\n\u001B[0m",
      "\u001B[0;32m~/PycharmProjects/Phynteny/phynteny_utils/train_model.py\u001B[0m in \u001B[0;36mperform_search\u001B[0;34m(self)\u001B[0m\n\u001B[1;32m    176\u001B[0m         \u001B[0mprint\u001B[0m\u001B[0;34m(\u001B[0m\u001B[0mself\u001B[0m\u001B[0;34m.\u001B[0m\u001B[0my\u001B[0m\u001B[0;34m.\u001B[0m\u001B[0mshape\u001B[0m\u001B[0;34m)\u001B[0m\u001B[0;34m\u001B[0m\u001B[0;34m\u001B[0m\u001B[0m\n\u001B[1;32m    177\u001B[0m \u001B[0;34m\u001B[0m\u001B[0m\n\u001B[0;32m--> 178\u001B[0;31m         \u001B[0msearch_result\u001B[0m \u001B[0;34m=\u001B[0m \u001B[0msearch\u001B[0m\u001B[0;34m.\u001B[0m\u001B[0mfit\u001B[0m\u001B[0;34m(\u001B[0m\u001B[0mself\u001B[0m\u001B[0;34m.\u001B[0m\u001B[0mX\u001B[0m\u001B[0;34m,\u001B[0m\u001B[0mself\u001B[0m\u001B[0;34m.\u001B[0m\u001B[0my\u001B[0m\u001B[0;34m)\u001B[0m\u001B[0;34m\u001B[0m\u001B[0;34m\u001B[0m\u001B[0m\n\u001B[0m\u001B[1;32m    179\u001B[0m \u001B[0;34m\u001B[0m\u001B[0m\n\u001B[1;32m    180\u001B[0m         \u001B[0;31m# evaluate the results of the grid search\u001B[0m\u001B[0;34m\u001B[0m\u001B[0;34m\u001B[0m\u001B[0;34m\u001B[0m\u001B[0m\n",
      "\u001B[0;32m~/opt/anaconda3/envs/phynteny/lib/python3.8/site-packages/sklearn/model_selection/_search.py\u001B[0m in \u001B[0;36mfit\u001B[0;34m(self, X, y, groups, **fit_params)\u001B[0m\n\u001B[1;32m    872\u001B[0m                 \u001B[0;32mreturn\u001B[0m \u001B[0mresults\u001B[0m\u001B[0;34m\u001B[0m\u001B[0;34m\u001B[0m\u001B[0m\n\u001B[1;32m    873\u001B[0m \u001B[0;34m\u001B[0m\u001B[0m\n\u001B[0;32m--> 874\u001B[0;31m             \u001B[0mself\u001B[0m\u001B[0;34m.\u001B[0m\u001B[0m_run_search\u001B[0m\u001B[0;34m(\u001B[0m\u001B[0mevaluate_candidates\u001B[0m\u001B[0;34m)\u001B[0m\u001B[0;34m\u001B[0m\u001B[0;34m\u001B[0m\u001B[0m\n\u001B[0m\u001B[1;32m    875\u001B[0m \u001B[0;34m\u001B[0m\u001B[0m\n\u001B[1;32m    876\u001B[0m             \u001B[0;31m# multimetric is determined here because in the case of a callable\u001B[0m\u001B[0;34m\u001B[0m\u001B[0;34m\u001B[0m\u001B[0;34m\u001B[0m\u001B[0m\n",
      "\u001B[0;32m~/opt/anaconda3/envs/phynteny/lib/python3.8/site-packages/sklearn/model_selection/_search.py\u001B[0m in \u001B[0;36m_run_search\u001B[0;34m(self, evaluate_candidates)\u001B[0m\n\u001B[1;32m   1386\u001B[0m     \u001B[0;32mdef\u001B[0m \u001B[0m_run_search\u001B[0m\u001B[0;34m(\u001B[0m\u001B[0mself\u001B[0m\u001B[0;34m,\u001B[0m \u001B[0mevaluate_candidates\u001B[0m\u001B[0;34m)\u001B[0m\u001B[0;34m:\u001B[0m\u001B[0;34m\u001B[0m\u001B[0;34m\u001B[0m\u001B[0m\n\u001B[1;32m   1387\u001B[0m         \u001B[0;34m\"\"\"Search all candidates in param_grid\"\"\"\u001B[0m\u001B[0;34m\u001B[0m\u001B[0;34m\u001B[0m\u001B[0m\n\u001B[0;32m-> 1388\u001B[0;31m         \u001B[0mevaluate_candidates\u001B[0m\u001B[0;34m(\u001B[0m\u001B[0mParameterGrid\u001B[0m\u001B[0;34m(\u001B[0m\u001B[0mself\u001B[0m\u001B[0;34m.\u001B[0m\u001B[0mparam_grid\u001B[0m\u001B[0;34m)\u001B[0m\u001B[0;34m)\u001B[0m\u001B[0;34m\u001B[0m\u001B[0;34m\u001B[0m\u001B[0m\n\u001B[0m\u001B[1;32m   1389\u001B[0m \u001B[0;34m\u001B[0m\u001B[0m\n\u001B[1;32m   1390\u001B[0m \u001B[0;34m\u001B[0m\u001B[0m\n",
      "\u001B[0;32m~/opt/anaconda3/envs/phynteny/lib/python3.8/site-packages/sklearn/model_selection/_search.py\u001B[0m in \u001B[0;36mevaluate_candidates\u001B[0;34m(candidate_params, cv, more_results)\u001B[0m\n\u001B[1;32m    819\u001B[0m                     )\n\u001B[1;32m    820\u001B[0m \u001B[0;34m\u001B[0m\u001B[0m\n\u001B[0;32m--> 821\u001B[0;31m                 out = parallel(\n\u001B[0m\u001B[1;32m    822\u001B[0m                     delayed(_fit_and_score)(\n\u001B[1;32m    823\u001B[0m                         \u001B[0mclone\u001B[0m\u001B[0;34m(\u001B[0m\u001B[0mbase_estimator\u001B[0m\u001B[0;34m)\u001B[0m\u001B[0;34m,\u001B[0m\u001B[0;34m\u001B[0m\u001B[0;34m\u001B[0m\u001B[0m\n",
      "\u001B[0;32m~/opt/anaconda3/envs/phynteny/lib/python3.8/site-packages/sklearn/utils/parallel.py\u001B[0m in \u001B[0;36m__call__\u001B[0;34m(self, iterable)\u001B[0m\n\u001B[1;32m     61\u001B[0m             \u001B[0;32mfor\u001B[0m \u001B[0mdelayed_func\u001B[0m\u001B[0;34m,\u001B[0m \u001B[0margs\u001B[0m\u001B[0;34m,\u001B[0m \u001B[0mkwargs\u001B[0m \u001B[0;32min\u001B[0m \u001B[0miterable\u001B[0m\u001B[0;34m\u001B[0m\u001B[0;34m\u001B[0m\u001B[0m\n\u001B[1;32m     62\u001B[0m         )\n\u001B[0;32m---> 63\u001B[0;31m         \u001B[0;32mreturn\u001B[0m \u001B[0msuper\u001B[0m\u001B[0;34m(\u001B[0m\u001B[0;34m)\u001B[0m\u001B[0;34m.\u001B[0m\u001B[0m__call__\u001B[0m\u001B[0;34m(\u001B[0m\u001B[0miterable_with_config\u001B[0m\u001B[0;34m)\u001B[0m\u001B[0;34m\u001B[0m\u001B[0;34m\u001B[0m\u001B[0m\n\u001B[0m\u001B[1;32m     64\u001B[0m \u001B[0;34m\u001B[0m\u001B[0m\n\u001B[1;32m     65\u001B[0m \u001B[0;34m\u001B[0m\u001B[0m\n",
      "\u001B[0;32m~/opt/anaconda3/envs/phynteny/lib/python3.8/site-packages/joblib/parallel.py\u001B[0m in \u001B[0;36m__call__\u001B[0;34m(self, iterable)\u001B[0m\n\u001B[1;32m   1096\u001B[0m \u001B[0;34m\u001B[0m\u001B[0m\n\u001B[1;32m   1097\u001B[0m             \u001B[0;32mwith\u001B[0m \u001B[0mself\u001B[0m\u001B[0;34m.\u001B[0m\u001B[0m_backend\u001B[0m\u001B[0;34m.\u001B[0m\u001B[0mretrieval_context\u001B[0m\u001B[0;34m(\u001B[0m\u001B[0;34m)\u001B[0m\u001B[0;34m:\u001B[0m\u001B[0;34m\u001B[0m\u001B[0;34m\u001B[0m\u001B[0m\n\u001B[0;32m-> 1098\u001B[0;31m                 \u001B[0mself\u001B[0m\u001B[0;34m.\u001B[0m\u001B[0mretrieve\u001B[0m\u001B[0;34m(\u001B[0m\u001B[0;34m)\u001B[0m\u001B[0;34m\u001B[0m\u001B[0;34m\u001B[0m\u001B[0m\n\u001B[0m\u001B[1;32m   1099\u001B[0m             \u001B[0;31m# Make sure that we get a last message telling us we are done\u001B[0m\u001B[0;34m\u001B[0m\u001B[0;34m\u001B[0m\u001B[0;34m\u001B[0m\u001B[0m\n\u001B[1;32m   1100\u001B[0m             \u001B[0melapsed_time\u001B[0m \u001B[0;34m=\u001B[0m \u001B[0mtime\u001B[0m\u001B[0;34m.\u001B[0m\u001B[0mtime\u001B[0m\u001B[0;34m(\u001B[0m\u001B[0;34m)\u001B[0m \u001B[0;34m-\u001B[0m \u001B[0mself\u001B[0m\u001B[0;34m.\u001B[0m\u001B[0m_start_time\u001B[0m\u001B[0;34m\u001B[0m\u001B[0;34m\u001B[0m\u001B[0m\n",
      "\u001B[0;32m~/opt/anaconda3/envs/phynteny/lib/python3.8/site-packages/joblib/parallel.py\u001B[0m in \u001B[0;36mretrieve\u001B[0;34m(self)\u001B[0m\n\u001B[1;32m    973\u001B[0m             \u001B[0;32mtry\u001B[0m\u001B[0;34m:\u001B[0m\u001B[0;34m\u001B[0m\u001B[0;34m\u001B[0m\u001B[0m\n\u001B[1;32m    974\u001B[0m                 \u001B[0;32mif\u001B[0m \u001B[0mgetattr\u001B[0m\u001B[0;34m(\u001B[0m\u001B[0mself\u001B[0m\u001B[0;34m.\u001B[0m\u001B[0m_backend\u001B[0m\u001B[0;34m,\u001B[0m \u001B[0;34m'supports_timeout'\u001B[0m\u001B[0;34m,\u001B[0m \u001B[0;32mFalse\u001B[0m\u001B[0;34m)\u001B[0m\u001B[0;34m:\u001B[0m\u001B[0;34m\u001B[0m\u001B[0;34m\u001B[0m\u001B[0m\n\u001B[0;32m--> 975\u001B[0;31m                     \u001B[0mself\u001B[0m\u001B[0;34m.\u001B[0m\u001B[0m_output\u001B[0m\u001B[0;34m.\u001B[0m\u001B[0mextend\u001B[0m\u001B[0;34m(\u001B[0m\u001B[0mjob\u001B[0m\u001B[0;34m.\u001B[0m\u001B[0mget\u001B[0m\u001B[0;34m(\u001B[0m\u001B[0mtimeout\u001B[0m\u001B[0;34m=\u001B[0m\u001B[0mself\u001B[0m\u001B[0;34m.\u001B[0m\u001B[0mtimeout\u001B[0m\u001B[0;34m)\u001B[0m\u001B[0;34m)\u001B[0m\u001B[0;34m\u001B[0m\u001B[0;34m\u001B[0m\u001B[0m\n\u001B[0m\u001B[1;32m    976\u001B[0m                 \u001B[0;32melse\u001B[0m\u001B[0;34m:\u001B[0m\u001B[0;34m\u001B[0m\u001B[0;34m\u001B[0m\u001B[0m\n\u001B[1;32m    977\u001B[0m                     \u001B[0mself\u001B[0m\u001B[0;34m.\u001B[0m\u001B[0m_output\u001B[0m\u001B[0;34m.\u001B[0m\u001B[0mextend\u001B[0m\u001B[0;34m(\u001B[0m\u001B[0mjob\u001B[0m\u001B[0;34m.\u001B[0m\u001B[0mget\u001B[0m\u001B[0;34m(\u001B[0m\u001B[0;34m)\u001B[0m\u001B[0;34m)\u001B[0m\u001B[0;34m\u001B[0m\u001B[0;34m\u001B[0m\u001B[0m\n",
      "\u001B[0;32m~/opt/anaconda3/envs/phynteny/lib/python3.8/site-packages/joblib/_parallel_backends.py\u001B[0m in \u001B[0;36mwrap_future_result\u001B[0;34m(future, timeout)\u001B[0m\n\u001B[1;32m    565\u001B[0m         AsyncResults.get from multiprocessing.\"\"\"\n\u001B[1;32m    566\u001B[0m         \u001B[0;32mtry\u001B[0m\u001B[0;34m:\u001B[0m\u001B[0;34m\u001B[0m\u001B[0;34m\u001B[0m\u001B[0m\n\u001B[0;32m--> 567\u001B[0;31m             \u001B[0;32mreturn\u001B[0m \u001B[0mfuture\u001B[0m\u001B[0;34m.\u001B[0m\u001B[0mresult\u001B[0m\u001B[0;34m(\u001B[0m\u001B[0mtimeout\u001B[0m\u001B[0;34m=\u001B[0m\u001B[0mtimeout\u001B[0m\u001B[0;34m)\u001B[0m\u001B[0;34m\u001B[0m\u001B[0;34m\u001B[0m\u001B[0m\n\u001B[0m\u001B[1;32m    568\u001B[0m         \u001B[0;32mexcept\u001B[0m \u001B[0mCfTimeoutError\u001B[0m \u001B[0;32mas\u001B[0m \u001B[0me\u001B[0m\u001B[0;34m:\u001B[0m\u001B[0;34m\u001B[0m\u001B[0;34m\u001B[0m\u001B[0m\n\u001B[1;32m    569\u001B[0m             \u001B[0;32mraise\u001B[0m \u001B[0mTimeoutError\u001B[0m \u001B[0;32mfrom\u001B[0m \u001B[0me\u001B[0m\u001B[0;34m\u001B[0m\u001B[0;34m\u001B[0m\u001B[0m\n",
      "\u001B[0;32m~/opt/anaconda3/envs/phynteny/lib/python3.8/concurrent/futures/_base.py\u001B[0m in \u001B[0;36mresult\u001B[0;34m(self, timeout)\u001B[0m\n\u001B[1;32m    437\u001B[0m                 \u001B[0;32mraise\u001B[0m \u001B[0mCancelledError\u001B[0m\u001B[0;34m(\u001B[0m\u001B[0;34m)\u001B[0m\u001B[0;34m\u001B[0m\u001B[0;34m\u001B[0m\u001B[0m\n\u001B[1;32m    438\u001B[0m             \u001B[0;32melif\u001B[0m \u001B[0mself\u001B[0m\u001B[0;34m.\u001B[0m\u001B[0m_state\u001B[0m \u001B[0;34m==\u001B[0m \u001B[0mFINISHED\u001B[0m\u001B[0;34m:\u001B[0m\u001B[0;34m\u001B[0m\u001B[0;34m\u001B[0m\u001B[0m\n\u001B[0;32m--> 439\u001B[0;31m                 \u001B[0;32mreturn\u001B[0m \u001B[0mself\u001B[0m\u001B[0;34m.\u001B[0m\u001B[0m__get_result\u001B[0m\u001B[0;34m(\u001B[0m\u001B[0;34m)\u001B[0m\u001B[0;34m\u001B[0m\u001B[0;34m\u001B[0m\u001B[0m\n\u001B[0m\u001B[1;32m    440\u001B[0m             \u001B[0;32melse\u001B[0m\u001B[0;34m:\u001B[0m\u001B[0;34m\u001B[0m\u001B[0;34m\u001B[0m\u001B[0m\n\u001B[1;32m    441\u001B[0m                 \u001B[0;32mraise\u001B[0m \u001B[0mTimeoutError\u001B[0m\u001B[0;34m(\u001B[0m\u001B[0;34m)\u001B[0m\u001B[0;34m\u001B[0m\u001B[0;34m\u001B[0m\u001B[0m\n",
      "\u001B[0;32m~/opt/anaconda3/envs/phynteny/lib/python3.8/concurrent/futures/_base.py\u001B[0m in \u001B[0;36m__get_result\u001B[0;34m(self)\u001B[0m\n\u001B[1;32m    386\u001B[0m     \u001B[0;32mdef\u001B[0m \u001B[0m__get_result\u001B[0m\u001B[0;34m(\u001B[0m\u001B[0mself\u001B[0m\u001B[0;34m)\u001B[0m\u001B[0;34m:\u001B[0m\u001B[0;34m\u001B[0m\u001B[0;34m\u001B[0m\u001B[0m\n\u001B[1;32m    387\u001B[0m         \u001B[0;32mif\u001B[0m \u001B[0mself\u001B[0m\u001B[0;34m.\u001B[0m\u001B[0m_exception\u001B[0m\u001B[0;34m:\u001B[0m\u001B[0;34m\u001B[0m\u001B[0;34m\u001B[0m\u001B[0m\n\u001B[0;32m--> 388\u001B[0;31m             \u001B[0;32mraise\u001B[0m \u001B[0mself\u001B[0m\u001B[0;34m.\u001B[0m\u001B[0m_exception\u001B[0m\u001B[0;34m\u001B[0m\u001B[0;34m\u001B[0m\u001B[0m\n\u001B[0m\u001B[1;32m    389\u001B[0m         \u001B[0;32melse\u001B[0m\u001B[0;34m:\u001B[0m\u001B[0;34m\u001B[0m\u001B[0;34m\u001B[0m\u001B[0m\n\u001B[1;32m    390\u001B[0m             \u001B[0;32mreturn\u001B[0m \u001B[0mself\u001B[0m\u001B[0;34m.\u001B[0m\u001B[0m_result\u001B[0m\u001B[0;34m\u001B[0m\u001B[0;34m\u001B[0m\u001B[0m\n",
      "\u001B[0;31mBrokenProcessPool\u001B[0m: A task has failed to un-serialize. Please ensure that the arguments of the function are all picklable."
     ]
    }
   ],
   "source": [
    "model = train_model.Model('phrog_annotation_info/integer_category.pkl') #create a model object\n",
    "\n",
    "model.parse_data(subset_dict)\n",
    "#created = model.generate_LSTM(layers = 0) #create a phynteny model which has one layer\n",
    "model.perform_search()"
   ],
   "metadata": {
    "collapsed": false
   }
  },
  {
   "cell_type": "code",
   "execution_count": 35,
   "outputs": [
    {
     "name": "stdout",
     "output_type": "stream",
     "text": [
      "1/1 [==============================] - 0s 28ms/step - loss: 2.4254 - accuracy: 0.0350\n"
     ]
    },
    {
     "data": {
      "text/plain": "<keras.callbacks.History at 0x7fa75ef0e070>"
     },
     "execution_count": 35,
     "metadata": {},
     "output_type": "execute_result"
    }
   ],
   "source": [],
   "metadata": {
    "collapsed": false
   }
  },
  {
   "cell_type": "code",
   "execution_count": 20,
   "outputs": [
    {
     "data": {
      "text/plain": "(10, 120, 16)"
     },
     "execution_count": 20,
     "metadata": {},
     "output_type": "execute_result"
    }
   ],
   "source": [
    "optimizer = keras.optimizers.RMSprop(lr=0.0003, decay=1e-6)X.shape"
   ],
   "metadata": {
    "collapsed": false
   }
  },
  {
   "cell_type": "code",
   "execution_count": null,
   "outputs": [],
   "source": [],
   "metadata": {
    "collapsed": false
   }
  }
 ],
 "metadata": {
  "kernelspec": {
   "display_name": "Python 3",
   "language": "python",
   "name": "python3"
  },
  "language_info": {
   "codemirror_mode": {
    "name": "ipython",
    "version": 2
   },
   "file_extension": ".py",
   "mimetype": "text/x-python",
   "name": "python",
   "nbconvert_exporter": "python",
   "pygments_lexer": "ipython2",
   "version": "2.7.6"
  }
 },
 "nbformat": 4,
 "nbformat_minor": 0
}
